Workbook

Sheet Instruções
A1: INSTRUÇÕES
A3: Aba Produtos
A4: 1. Inserir o Código do Produto, descrição e estoque mínimo.
A5: 2. Os campos Estoque Atual e Situação são gerados automaticamente através de fórmulas, portanto não devem ser alterados manualmente.
A7: Aba Movimentos
A8: 1. Inserir os movimentos de Entradas e Saídas dos produtos (Data, Tipo, Cód Produto e Quantidade)
A9: 2. O campo Descrição é gerado automaticamente através de fórmulas, portanto não deve ser alterado manualmente.
A11: Aba Resumo
A12: 1. Alterar somente o Ano que deseja visualizar os gráficos, e o Código do Produto que deseja consultar (campo amarelo).
A13: 2. Todos os outros campos são gerados automaticamente através de fórmulas, portanto não devem ser alterados manualmente.

Sheet Produtos
A1: PRODUTOS
B3: Cód | C3: Descrição | D3: Estoque Mínimo | E3: Estoque Atual | F3: Situação
A4: =IF(F4="Saldo zerado",0,IF(F4="Saldo abaixo do mínimo",1,IF(F4="Saldo disponível",2,"."))) -> 2 | B4: P001 | C4: ADUELA DE 1000 | D4: 50 | E4: =IFERROR(IF(AND(B4<>"",C4<>""),SUMIFS(Movimentos!$F$4:$F$9996,Movimentos!$D$4:$D$9996,B4,Movimentos!$C$4:$C$9996,"Entrada")-SUMIFS(Movimentos!$F$4:$F$9996,Movimentos!$D$4:$D$9996,B4,Movimentos!$C$4:$C$9996,"Saída"),""),"") -> 69 | F4: =IF(AND(B4<>"",C4<>""),IF(E4=0,"Saldo zerado",IF(E4<D4,"Saldo abaixo do mínimo","Saldo disponível")),"") -> Saldo disponível
A5: =IF(F5="Saldo zerado",0,IF(F5="Saldo abaixo do mínimo",1,IF(F5="Saldo disponível",2,"."))) -> 2 | B5: P002 | C5: ADUELA DE 600 | D5: 80 | E5: =IFERROR(IF(AND(B5<>"",C5<>""),SUMIFS(Movimentos!$F$4:$F$9996,Movimentos!$D$4:$D$9996,B5,Movimentos!$C$4:$C$9996,"Entrada")-SUMIFS(Movimentos!$F$4:$F$9996,Movimentos!$D$4:$D$9996,B5,Movimentos!$C$4:$C$9996,"Saída"),""),"") -> 95 | F5: =IF(AND(B5<>"",C5<>""),IF(E5=0,"Saldo zerado",IF(E5<D5,"Saldo abaixo do mínimo","Saldo disponível")),"") -> Saldo disponível
A6: =IF(F6="Saldo zerado",0,IF(F6="Saldo abaixo do mínimo",1,IF(F6="Saldo disponível",2,"."))) -> 2 | B6: P003 | C6: LAJE INFERIOR DE 1000 | D6: 10 | E6: =IFERROR(IF(AND(B6<>"",C6<>""),SUMIFS(Movimentos!$F$4:$F$9996,Movimentos!$D$4:$D$9996,B6,Movimentos!$C$4:$C$9996,"Entrada")-SUMIFS(Movimentos!$F$4:$F$9996,Movimentos!$D$4:$D$9996,B6,Movimentos!$C$4:$C$9996,"Saída"),""),"") -> 19 | F6: =IF(AND(B6<>"",C6<>""),IF(E6=0,"Saldo zerado",IF(E6<D6,"Saldo abaixo do mínimo","Saldo disponível")),"") -> Saldo disponível
A7: =IF(F7="Saldo zerado",0,IF(F7="Saldo abaixo do mínimo",1,IF(F7="Saldo disponível",2,"."))) -> 2 | B7: P004 | C7: LAJE INFERIOR DE 600 | D7: 50 | E7: =IFERROR(IF(AND(B7<>"",C7<>""),SUMIFS(Movimentos!$F$4:$F$9996,Movimentos!$D$4:$D$9996,B7,Movimentos!$C$4:$C$9996,"Entrada")-SUMIFS(Movimentos!$F$4:$F$9996,Movimentos!$D$4:$D$9996,B7,Movimentos!$C$4:$C$9996,"Saída"),""),"") -> 166 | F7: =IF(AND(B7<>"",C7<>""),IF(E7=0,"Saldo zerado",IF(E7<D7,"Saldo abaixo do mínimo","Saldo disponível")),"") -> Saldo disponível
A8: =IF(F8="Saldo zerado",0,IF(F8="Saldo abaixo do mínimo",1,IF(F8="Saldo disponível",2,"."))) -> 2 | B8: P005 | C8: LAJE SURPERIOR DE 1000 | D8: 10 | E8: =IFERROR(IF(AND(B8<>"",C8<>""),SUMIFS(Movimentos!$F$4:$F$9996,Movimentos!$D$4:$D$9996,B8,Movimentos!$C$4:$C$9996,"Entrada")-SUMIFS(Movimentos!$F$4:$F$9996,Movimentos!$D$4:$D$9996,B8,Movimentos!$C$4:$C$9996,"Saída"),""),"") -> 39 | F8: =IF(AND(B8<>"",C8<>""),IF(E8=0,"Saldo zerado",IF(E8<D8,"Saldo abaixo do mínimo","Saldo disponível")),"") -> Saldo disponível
A9: =IF(F9="Saldo zerado",0,IF(F9="Saldo abaixo do mínimo",1,IF(F9="Saldo disponível",2,"."))) -> 2 | B9: P006 | C9: TUBO PEAD ESGOTO D 355 | D9: 200 | E9: =IFERROR(IF(AND(B9<>"",C9<>""),SUMIFS(Movimentos!$F$4:$F$9996,Movimentos!$D$4:$D$9996,B9,Movimentos!$C$4:$C$9996,"Entrada")-SUMIFS(Movimentos!$F$4:$F$9996,Movimentos!$D$4:$D$9996,B9,Movimentos!$C$4:$C$9996,"Saída"),""),"") -> 389 | F9: =IF(AND(B9<>"",C9<>""),IF(E9=0,"Saldo zerado",IF(E9<D9,"Saldo abaixo do mínimo","Saldo disponível")),"") -> Saldo disponível
A10: =IF(F10="Saldo zerado",0,IF(F10="Saldo abaixo do mínimo",1,IF(F10="Saldo disponível",2,"."))) -> 1 | B10: P007 | C10: TUBO PEAD ESGOTO D 315 | D10: 10 | E10: =IFERROR(IF(AND(B10<>"",C10<>""),SUMIFS(Movimentos!$F$4:$F$9996,Movimentos!$D$4:$D$9996,B10,Movimentos!$C$4:$C$9996,"Entrada")-SUMIFS(Movimentos!$F$4:$F$9996,Movimentos!$D$4:$D$9996,B10,Movimentos!$C$4:$C$9996,"Saída"),""),"") -> 2 | F10: =IF(AND(B10<>"",C10<>""),IF(E10=0,"Saldo zerado",IF(E10<D10,"Saldo abaixo do mínimo","Saldo disponível")),"") -> Saldo abaixo do mínimo
A11: =IF(F11="Saldo zerado",0,IF(F11="Saldo abaixo do mínimo",1,IF(F11="Saldo disponível",2,"."))) -> 2 | B11: P008 | C11: TUBO PEAD ESGOTO D 225 | D11: 10 | E11: =IFERROR(IF(AND(B11<>"",C11<>""),SUMIFS(Movimentos!$F$4:$F$9996,Movimentos!$D$4:$D$9996,B11,Movimentos!$C$4:$C$9996,"Entrada")-SUMIFS(Movimentos!$F$4:$F$9996,Movimentos!$D$4:$D$9996,B11,Movimentos!$C$4:$C$9996,"Saída"),""),"") -> 239 | F11: =IF(AND(B11<>"",C11<>""),IF(E11=0,"Saldo zerado",IF(E11<D11,"Saldo abaixo do mínimo","Saldo disponível")),"") -> Saldo disponível
A12: =IF(F12="Saldo zerado",0,IF(F12="Saldo abaixo do mínimo",1,IF(F12="Saldo disponível",2,"."))) -> 2 | B12: P009 | C12: TUBO PEAD ESGOTO D 450 | D12: 30 | E12: =IFERROR(IF(AND(B12<>"",C12<>""),SUMIFS(Movimentos!$F$4:$F$9996,Movimentos!$D$4:$D$9996,B12,Movimentos!$C$4:$C$9996,"Entrada")-SUMIFS(Movimentos!$F$4:$F$9996,Movimentos!$D$4:$D$9996,B12,Movimentos!$C$4:$C$9996,"Saída"),""),"") -> 111 | F12: =IF(AND(B12<>"",C12<>""),IF(E12=0,"Saldo zerado",IF(E12<D12,"Saldo abaixo do mínimo","Saldo disponível")),"") -> Saldo disponível
A13: =IF(F13="Saldo zerado",0,IF(F13="Saldo abaixo do mínimo",1,IF(F13="Saldo disponível",2,"."))) -> 2 | B13: P010 | C13: TUBO CURRUGADO ESGOTO DN 300 | D13: 10 | E13: =IFERROR(IF(AND(B13<>"",C13<>""),SUMIFS(Movimentos!$F$4:$F$9996,Movimentos!$D$4:$D$9996,B13,Movimentos!$C$4:$C$9996,"Entrada")-SUMIFS(Movimentos!$F$4:$F$9996,Movimentos!$D$4:$D$9996,B13,Movimentos!$C$4:$C$9996,"Saída"),""),"") -> 193 | F13: =IF(AND(B13<>"",C13<>""),IF(E13=0,"Saldo zerado",IF(E13<D13,"Saldo abaixo do mínimo","Saldo disponível")),"") -> Saldo disponível
A14: =IF(F14="Saldo zerado",0,IF(F14="Saldo abaixo do mínimo",1,IF(F14="Saldo disponível",2,"."))) -> 2 | B14: P011 | C14: TUBO ESGOTO PVC DN 300 | D14: 10 | E14: =IFERROR(IF(AND(B14<>"",C14<>""),SUMIFS(Movimentos!$F$4:$F$9996,Movimentos!$D$4:$D$9996,B14,Movimentos!$C$4:$C$9996,"Entrada")-SUMIFS(Movimentos!$F$4:$F$9996,Movimentos!$D$4:$D$9996,B14,Movimentos!$C$4:$C$9996,"Saída"),""),"") -> 284 | F14: =IF(AND(B14<>"",C14<>""),IF(E14=0,"Saldo zerado",IF(E14<D14,"Saldo abaixo do mínimo","Saldo disponível")),"") -> Saldo disponível
A15: =IF(F15="Saldo zerado",0,IF(F15="Saldo abaixo do mínimo",1,IF(F15="Saldo disponível",2,"."))) -> 2 | B15: P012 | C15: TUBO ESGOTO PVC DN 200 | D15: 10 | E15: =IFERROR(IF(AND(B15<>"",C15<>""),SUMIFS(Movimentos!$F$4:$F$9996,Movimentos!$D$4:$D$9996,B15,Movimentos!$C$4:$C$9996,"Entrada")-SUMIFS(Movimentos!$F$4:$F$9996,Movimentos!$D$4:$D$9996,B15,Movimentos!$C$4:$C$9996,"Saída"),""),"") -> 89 | F15: =IF(AND(B15<>"",C15<>""),IF(E15=0,"Saldo zerado",IF(E15<D15,"Saldo abaixo do mínimo","Saldo disponível")),"") -> Saldo disponível
... A31: =IF(F31="Saldo zerado",0,IF(F31="Saldo abaixo do mínimo",1,IF(F31="Saldo disponível",2,"."))) -> 2 | B31: P028 | C31: ANEIS DE BORRACHA PARA PV 1000x1000 | D31: 10 | E31: =IFERROR(IF(AND(B31<>"",C31<>""),SUMIFS(Movimentos!$F$4:$F$9996,Movimentos!$D$4:$D$9996,B31,Movimentos!$C$4:$C$9996,"Entrada")-SUMIFS(Movimentos!$F$4:$F$9996,Movimentos!$D$4:$D$9996,B31,Movimentos!$C$4:$C$9996,"Saída"),""),"") -> 61 | F31: =IF(AND(B31<>"",C31<>""),IF(E31=0,"Saldo zerado",IF(E31<D31,"Saldo abaixo do mínimo","Saldo disponível")),"") -> Saldo disponível
A32: =IF(F32="Saldo zerado",0,IF(F32="Saldo abaixo do mínimo",1,IF(F32="Saldo disponível",2,"."))) -> . | B32: P029 | D32: 10 | E32: =IFERROR(IF(AND(B32<>"",C32<>""),SUMIFS(Movimentos!$F$4:$F$9996,Movimentos!$D$4:$D$9996,B32,Movimentos!$C$4:$C$9996,"Entrada")-SUMIFS(Movimentos!$F$4:$F$9996,Movimentos!$D$4:$D$9996,B32,Movimentos!$C$4:$C$9996,"Saída"),""),"") | F32: =IF(AND(B32<>"",C32<>""),IF(E32=0,"Saldo zerado",IF(E32<D32,"Saldo abaixo do mínimo","Saldo disponível")),"")
A33: =IF(F33="Saldo zerado",0,IF(F33="Saldo abaixo do mínimo",1,IF(F33="Saldo disponível",2,"."))) -> . | B33: P030 | D33: 10 | E33: =IFERROR(IF(AND(B33<>"",C33<>""),SUMIFS(Movimentos!$F$4:$F$9996,Movimentos!$D$4:$D$9996,B33,Movimentos!$C$4:$C$9996,"Entrada")-SUMIFS(Movimentos!$F$4:$F$9996,Movimentos!$D$4:$D$9996,B33,Movimentos!$C$4:$C$9996,"Saída"),""),"") | F33: =IF(AND(B33<>"",C33<>""),IF(E33=0,"Saldo zerado",IF(E33<D33,"Saldo abaixo do mínimo","Saldo disponível")),"")
A34: =IF(F34="Saldo zerado",0,IF(F34="Saldo abaixo do mínimo",1,IF(F34="Saldo disponível",2,"."))) -> . | B34: P031 | D34: 10 | E34: =IFERROR(IF(AND(B34<>"",C34<>""),SUMIFS(Movimentos!$F$4:$F$9996,Movimentos!$D$4:$D$9996,B34,Movimentos!$C$4:$C$9996,"Entrada")-SUMIFS(Movimentos!$F$4:$F$9996,Movimentos!$D$4:$D$9996,B34,Movimentos!$C$4:$C$9996,"Saída"),""),"") | F34: =IF(AND(B34<>"",C34<>""),IF(E34=0,"Saldo zerado",IF(E34<D34,"Saldo abaixo do mínimo","Saldo disponível")),"")
A35: =IF(F35="Saldo zerado",0,IF(F35="Saldo abaixo do mínimo",1,IF(F35="Saldo disponível",2,"."))) -> . | B35: P032 | D35: 10 | E35: =IFERROR(IF(AND(B35<>"",C35<>""),SUMIFS(Movimentos!$F$4:$F$9996,Movimentos!$D$4:$D$9996,B35,Movimentos!$C$4:$C$9996,"Entrada")-SUMIFS(Movimentos!$F$4:$F$9996,Movimentos!$D$4:$D$9996,B35,Movimentos!$C$4:$C$9996,"Saída"),""),"") | F35: =IF(AND(B35<>"",C35<>""),IF(E35=0,"Saldo zerado",IF(E35<D35,"Saldo abaixo do mínimo","Saldo disponível")),"")
A36: =IF(F36="Saldo zerado",0,IF(F36="Saldo abaixo do mínimo",1,IF(F36="Saldo disponível",2,"."))) -> . | B36: P033 | D36: 10 | E36: =IFERROR(IF(AND(B36<>"",C36<>""),SUMIFS(Movimentos!$F$4:$F$9996,Movimentos!$D$4:$D$9996,B36,Movimentos!$C$4:$C$9996,"Entrada")-SUMIFS(Movimentos!$F$4:$F$9996,Movimentos!$D$4:$D$9996,B36,Movimentos!$C$4:$C$9996,"Saída"),""),"") | F36: =IF(AND(B36<>"",C36<>""),IF(E36=0,"Saldo zerado",IF(E36<D36,"Saldo abaixo do mínimo","Saldo disponível")),"")
A37: =IF(F37="Saldo zerado",0,IF(F37="Saldo abaixo do mínimo",1,IF(F37="Saldo disponível",2,"."))) -> . | B37: P034 | D37: 10 | E37: =IFERROR(IF(AND(B37<>"",C37<>""),SUMIFS(Movimentos!$F$4:$F$9996,Movimentos!$D$4:$D$9996,B37,Movimentos!$C$4:$C$9996,"Entrada")-SUMIFS(Movimentos!$F$4:$F$9996,Movimentos!$D$4:$D$9996,B37,Movimentos!$C$4:$C$9996,"Saída"),""),"") | F37: =IF(AND(B37<>"",C37<>""),IF(E37=0,"Saldo zerado",IF(E37<D37,"Saldo abaixo do mínimo","Saldo disponível")),"")
A38: =IF(F38="Saldo zerado",0,IF(F38="Saldo abaixo do mínimo",1,IF(F38="Saldo disponível",2,"."))) -> . | B38: P035 | D38: 10 | E38: =IFERROR(IF(AND(B38<>"",C38<>""),SUMIFS(Movimentos!$F$4:$F$9996,Movimentos!$D$4:$D$9996,B38,Movimentos!$C$4:$C$9996,"Entrada")-SUMIFS(Movimentos!$F$4:$F$9996,Movimentos!$D$4:$D$9996,B38,Movimentos!$C$4:$C$9996,"Saída"),""),"") | F38: =IF(AND(B38<>"",C38<>""),IF(E38=0,"Saldo zerado",IF(E38<D38,"Saldo abaixo do mínimo","Saldo disponível")),"")
A39: =IF(F39="Saldo zerado",0,IF(F39="Saldo abaixo do mínimo",1,IF(F39="Saldo disponível",2,"."))) -> . | B39: P036 | D39: 10 | E39: =IFERROR(IF(AND(B39<>"",C39<>""),SUMIFS(Movimentos!$F$4:$F$9996,Movimentos!$D$4:$D$9996,B39,Movimentos!$C$4:$C$9996,"Entrada")-SUMIFS(Movimentos!$F$4:$F$9996,Movimentos!$D$4:$D$9996,B39,Movimentos!$C$4:$C$9996,"Saída"),""),"") | F39: =IF(AND(B39<>"",C39<>""),IF(E39=0,"Saldo zerado",IF(E39<D39,"Saldo abaixo do mínimo","Saldo disponível")),"")
A40: =IF(F40="Saldo zerado",0,IF(F40="Saldo abaixo do mínimo",1,IF(F40="Saldo disponível",2,"."))) -> . | B40: P037 | D40: 10 | E40: =IFERROR(IF(AND(B40<>"",C40<>""),SUMIFS(Movimentos!$F$4:$F$9996,Movimentos!$D$4:$D$9996,B40,Movimentos!$C$4:$C$9996,"Entrada")-SUMIFS(Movimentos!$F$4:$F$9996,Movimentos!$D$4:$D$9996,B40,Movimentos!$C$4:$C$9996,"Saída"),""),"") | F40: =IF(AND(B40<>"",C40<>""),IF(E40=0,"Saldo zerado",IF(E40<D40,"Saldo abaixo do mínimo","Saldo disponível")),"")
A41: =IF(F41="Saldo zerado",0,IF(F41="Saldo abaixo do mínimo",1,IF(F41="Saldo disponível",2,"."))) -> . | B41: P038 | D41: 10 | E41: =IFERROR(IF(AND(B41<>"",C41<>""),SUMIFS(Movimentos!$F$4:$F$9996,Movimentos!$D$4:$D$9996,B41,Movimentos!$C$4:$C$9996,"Entrada")-SUMIFS(Movimentos!$F$4:$F$9996,Movimentos!$D$4:$D$9996,B41,Movimentos!$C$4:$C$9996,"Saída"),""),"") | F41: =IF(AND(B41<>"",C41<>""),IF(E41=0,"Saldo zerado",IF(E41<D41,"Saldo abaixo do mínimo","Saldo disponível")),"")
A42: =IF(F42="Saldo zerado",0,IF(F42="Saldo abaixo do mínimo",1,IF(F42="Saldo disponível",2,"."))) -> . | B42: P039 | D42: 10 | E42: =IFERROR(IF(AND(B42<>"",C42<>""),SUMIFS(Movimentos!$F$4:$F$9996,Movimentos!$D$4:$D$9996,B42,Movimentos!$C$4:$C$9996,"Entrada")-SUMIFS(Movimentos!$F$4:$F$9996,Movimentos!$D$4:$D$9996,B42,Movimentos!$C$4:$C$9996,"Saída"),""),"") | F42: =IF(AND(B42<>"",C42<>""),IF(E42=0,"Saldo zerado",IF(E42<D42,"Saldo abaixo do mínimo","Saldo disponível")),"")
A43: =IF(F43="Saldo zerado",0,IF(F43="Saldo abaixo do mínimo",1,IF(F43="Saldo disponível",2,"."))) -> . | B43: P040 | D43: 10 | E43: =IFERROR(IF(AND(B43<>"",C43<>""),SUMIFS(Movimentos!$F$4:$F$9996,Movimentos!$D$4:$D$9996,B43,Movimentos!$C$4:$C$9996,"Entrada")-SUMIFS(Movimentos!$F$4:$F$9996,Movimentos!$D$4:$D$9996,B43,Movimentos!$C$4:$C$9996,"Saída"),""),"") | F43: =IF(AND(B43<>"",C43<>""),IF(E43=0,"Saldo zerado",IF(E43<D43,"Saldo abaixo do mínimo","Saldo disponível")),"")
... A97: =IF(F97="Saldo zerado",0,IF(F97="Saldo abaixo do mínimo",1,IF(F97="Saldo disponível",2,"."))) -> . | B97: P094 | D97: 10 | E97: =IFERROR(IF(AND(B97<>"",C97<>""),SUMIFS(Movimentos!$F$4:$F$9996,Movimentos!$D$4:$D$9996,B97,Movimentos!$C$4:$C$9996,"Entrada")-SUMIFS(Movimentos!$F$4:$F$9996,Movimentos!$D$4:$D$9996,B97,Movimentos!$C$4:$C$9996,"Saída"),""),"") | F97: =IF(AND(B97<>"",C97<>""),IF(E97=0,"Saldo zerado",IF(E97<D97,"Saldo abaixo do mínimo","Saldo disponível")),"")
A98: =IF(F98="Saldo zerado",0,IF(F98="Saldo abaixo do mínimo",1,IF(F98="Saldo disponível",2,"."))) -> . | E98: =IFERROR(IF(AND(B98<>"",C98<>""),SUMIFS(Movimentos!$F$4:$F$9996,Movimentos!$D$4:$D$9996,B98,Movimentos!$C$4:$C$9996,"Entrada")-SUMIFS(Movimentos!$F$4:$F$9996,Movimentos!$D$4:$D$9996,B98,Movimentos!$C$4:$C$9996,"Saída"),""),"") | F98: =IF(AND(B98<>"",C98<>""),IF(E98=0,"Saldo zerado",IF(E98<D98,"Saldo abaixo do mínimo","Saldo disponível")),"")
A99: =IF(F99="Saldo zerado",0,IF(F99="Saldo abaixo do mínimo",1,IF(F99="Saldo disponível",2,"."))) -> . | E99: =IFERROR(IF(AND(B99<>"",C99<>""),SUMIFS(Movimentos!$F$4:$F$9996,Movimentos!$D$4:$D$9996,B99,Movimentos!$C$4:$C$9996,"Entrada")-SUMIFS(Movimentos!$F$4:$F$9996,Movimentos!$D$4:$D$9996,B99,Movimentos!$C$4:$C$9996,"Saída"),""),"") | F99: =IF(AND(B99<>"",C99<>""),IF(E99=0,"Saldo zerado",IF(E99<D99,"Saldo abaixo do mínimo","Saldo disponível")),"")
A100: =IF(F100="Saldo zerado",0,IF(F100="Saldo abaixo do mínimo",1,IF(F100="Saldo disponível",2,"."))) -> . | E100: =IFERROR(IF(AND(B100<>"",C100<>""),SUMIFS(Movimentos!$F$4:$F$9996,Movimentos!$D$4:$D$9996,B100,Movimentos!$C$4:$C$9996,"Entrada")-SUMIFS(Movimentos!$F$4:$F$9996,Movimentos!$D$4:$D$9996,B100,Movimentos!$C$4:$C$9996,"Saída"),""),"") | F100: =IF(AND(B100<>"",C100<>""),IF(E100=0,"Saldo zerado",IF(E100<D100,"Saldo abaixo do mínimo","Saldo disponível")),"")
A101: =IF(F101="Saldo zerado",0,IF(F101="Saldo abaixo do mínimo",1,IF(F101="Saldo disponível",2,"."))) -> . | E101: =IFERROR(IF(AND(B101<>"",C101<>""),SUMIFS(Movimentos!$F$4:$F$9996,Movimentos!$D$4:$D$9996,B101,Movimentos!$C$4:$C$9996,"Entrada")-SUMIFS(Movimentos!$F$4:$F$9996,Movimentos!$D$4:$D$9996,B101,Movimentos!$C$4:$C$9996,"Saída"),""),"") | F101: =IF(AND(B101<>"",C101<>""),IF(E101=0,"Saldo zerado",IF(E101<D101,"Saldo abaixo do mínimo","Saldo disponível")),"")
A102: =IF(F102="Saldo zerado",0,IF(F102="Saldo abaixo do mínimo",1,IF(F102="Saldo disponível",2,"."))) -> . | E102: =IFERROR(IF(AND(B102<>"",C102<>""),SUMIFS(Movimentos!$F$4:$F$9996,Movimentos!$D$4:$D$9996,B102,Movimentos!$C$4:$C$9996,"Entrada")-SUMIFS(Movimentos!$F$4:$F$9996,Movimentos!$D$4:$D$9996,B102,Movimentos!$C$4:$C$9996,"Saída"),""),"") | F102: =IF(AND(B102<>"",C102<>""),IF(E102=0,"Saldo zerado",IF(E102<D102,"Saldo abaixo do mínimo","Saldo disponível")),"")
A103: =IF(F103="Saldo zerado",0,IF(F103="Saldo abaixo do mínimo",1,IF(F103="Saldo disponível",2,"."))) -> . | E103: =IFERROR(IF(AND(B103<>"",C103<>""),SUMIFS(Movimentos!$F$4:$F$9996,Movimentos!$D$4:$D$9996,B103,Movimentos!$C$4:$C$9996,"Entrada")-SUMIFS(Movimentos!$F$4:$F$9996,Movimentos!$D$4:$D$9996,B103,Movimentos!$C$4:$C$9996,"Saída"),""),"") | F103: =IF(AND(B103<>"",C103<>""),IF(E103=0,"Saldo zerado",IF(E103<D103,"Saldo abaixo do mínimo","Saldo disponível")),"")
A104: =IF(F104="Saldo zerado",0,IF(F104="Saldo abaixo do mínimo",1,IF(F104="Saldo disponível",2,"."))) -> . | E104: =IFERROR(IF(AND(B104<>"",C104<>""),SUMIFS(Movimentos!$F$4:$F$9996,Movimentos!$D$4:$D$9996,B104,Movimentos!$C$4:$C$9996,"Entrada")-SUMIFS(Movimentos!$F$4:$F$9996,Movimentos!$D$4:$D$9996,B104,Movimentos!$C$4:$C$9996,"Saída"),""),"") | F104: =IF(AND(B104<>"",C104<>""),IF(E104=0,"Saldo zerado",IF(E104<D104,"Saldo abaixo do mínimo","Saldo disponível")),"")
A105: =IF(F105="Saldo zerado",0,IF(F105="Saldo abaixo do mínimo",1,IF(F105="Saldo disponível",2,"."))) -> . | E105: =IFERROR(IF(AND(B105<>"",C105<>""),SUMIFS(Movimentos!$F$4:$F$9996,Movimentos!$D$4:$D$9996,B105,Movimentos!$C$4:$C$9996,"Entrada")-SUMIFS(Movimentos!$F$4:$F$9996,Movimentos!$D$4:$D$9996,B105,Movimentos!$C$4:$C$9996,"Saída"),""),"") | F105: =IF(AND(B105<>"",C105<>""),IF(E105=0,"Saldo zerado",IF(E105<D105,"Saldo abaixo do mínimo","Saldo disponível")),"")
A106: =IF(F106="Saldo zerado",0,IF(F106="Saldo abaixo do mínimo",1,IF(F106="Saldo disponível",2,"."))) -> . | E106: =IFERROR(IF(AND(B106<>"",C106<>""),SUMIFS(Movimentos!$F$4:$F$9996,Movimentos!$D$4:$D$9996,B106,Movimentos!$C$4:$C$9996,"Entrada")-SUMIFS(Movimentos!$F$4:$F$9996,Movimentos!$D$4:$D$9996,B106,Movimentos!$C$4:$C$9996,"Saída"),""),"") | F106: =IF(AND(B106<>"",C106<>""),IF(E106=0,"Saldo zerado",IF(E106<D106,"Saldo abaixo do mínimo","Saldo disponível")),"")
A107: =IF(F107="Saldo zerado",0,IF(F107="Saldo abaixo do mínimo",1,IF(F107="Saldo disponível",2,"."))) -> . | E107: =IFERROR(IF(AND(B107<>"",C107<>""),SUMIFS(Movimentos!$F$4:$F$9996,Movimentos!$D$4:$D$9996,B107,Movimentos!$C$4:$C$9996,"Entrada")-SUMIFS(Movimentos!$F$4:$F$9996,Movimentos!$D$4:$D$9996,B107,Movimentos!$C$4:$C$9996,"Saída"),""),"") | F107: =IF(AND(B107<>"",C107<>""),IF(E107=0,"Saldo zerado",IF(E107<D107,"Saldo abaixo do mínimo","Saldo disponível")),"")
A108: =IF(F108="Saldo zerado",0,IF(F108="Saldo abaixo do mínimo",1,IF(F108="Saldo disponível",2,"."))) -> . | E108: =IFERROR(IF(AND(B108<>"",C108<>""),SUMIFS(Movimentos!$F$4:$F$9996,Movimentos!$D$4:$D$9996,B108,Movimentos!$C$4:$C$9996,"Entrada")-SUMIFS(Movimentos!$F$4:$F$9996,Movimentos!$D$4:$D$9996,B108,Movimentos!$C$4:$C$9996,"Saída"),""),"") | F108: =IF(AND(B108<>"",C108<>""),IF(E108=0,"Saldo zerado",IF(E108<D108,"Saldo abaixo do mínimo","Saldo disponível")),"")
A109: =IF(F109="Saldo zerado",0,IF(F109="Saldo abaixo do mínimo",1,IF(F109="Saldo disponível",2,"."))) -> . | E109: =IFERROR(IF(AND(B109<>"",C109<>""),SUMIFS(Movimentos!$F$4:$F$9996,Movimentos!$D$4:$D$9996,B109,Movimentos!$C$4:$C$9996,"Entrada")-SUMIFS(Movimentos!$F$4:$F$9996,Movimentos!$D$4:$D$9996,B109,Movimentos!$C$4:$C$9996,"Saída"),""),"") | F109: =IF(AND(B109<>"",C109<>""),IF(E109=0,"Saldo zerado",IF(E109<D109,"Saldo abaixo do mínimo","Saldo disponível")),"")
...

Sheet Movimentos
A1: MOVIMENTOS
B3: Data | C3: Tipo | D3: Cód Produto | E3: Descrição do Produto | F3: Quantidade | G3: REQUISITANTE | H3: OBS
A4: =IF(C4="Entrada",2,IF(C4="Saída",1,".")) -> 2 | B4: 46063 | C4: Entrada | D4: P001 | E4: =IF(D4<>"",IFERROR(INDEX(Produtos!$C$4:$C$4996,MATCH(D4,Produtos!$B$4:$B$4996,0)),"Produto não encontrado"),"") -> ADUELA DE 1000 | F4: 98
A5: =IF(C5="Entrada",2,IF(C5="Saída",1,".")) -> 2 | B5: 46063 | C5: Entrada | D5: P002 | E5: =IF(D5<>"",IFERROR(INDEX(Produtos!$C$4:$C$4996,MATCH(D5,Produtos!$B$4:$B$4996,0)),"Produto não encontrado"),"") -> ADUELA DE 600 | F5: 212
A6: =IF(C6="Entrada",2,IF(C6="Saída",1,".")) -> 2 | B6: 46063 | C6: Entrada | D6: P003 | E6: =IF(D6<>"",IFERROR(INDEX(Produtos!$C$4:$C$4996,MATCH(D6,Produtos!$B$4:$B$4996,0)),"Produto não encontrado"),"") -> LAJE INFERIOR DE 1000 | F6: 42
A7: =IF(C7="Entrada",2,IF(C7="Saída",1,".")) -> 2 | B7: 46063 | C7: Entrada | D7: P004 | E7: =IF(D7<>"",IFERROR(INDEX(Produtos!$C$4:$C$4996,MATCH(D7,Produtos!$B$4:$B$4996,0)),"Produto não encontrado"),"") -> LAJE INFERIOR DE 600 | F7: 121
A8: =IF(C8="Entrada",2,IF(C8="Saída",1,".")) -> 2 | B8: 46063 | C8: Entrada | D8: P005 | E8: =IF(D8<>"",IFERROR(INDEX(Produtos!$C$4:$C$4996,MATCH(D8,Produtos!$B$4:$B$4996,0)),"Produto não encontrado"),"") -> LAJE SURPERIOR DE 1000 | F8: 18
A9: =IF(C9="Entrada",2,IF(C9="Saída",1,".")) -> 2 | B9: 46063 | C9: Entrada | D9: P006 | E9: =IF(D9<>"",IFERROR(INDEX(Produtos!$C$4:$C$4996,MATCH(D9,Produtos!$B$4:$B$4996,0)),"Produto não encontrado"),"") -> TUBO PEAD ESGOTO D 355 | F9: 1084
A10: =IF(C10="Entrada",2,IF(C10="Saída",1,".")) -> 2 | B10: 46063 | C10: Entrada | D10: P007 | E10: =IF(D10<>"",IFERROR(INDEX(Produtos!$C$4:$C$4996,MATCH(D10,Produtos!$B$4:$B$4996,0)),"Produto não encontrado"),"") -> TUBO PEAD ESGOTO D 315 | F10: 30
A11: =IF(C11="Entrada",2,IF(C11="Saída",1,".")) -> 2 | B11: 46063 | C11: Entrada | D11: P008 | E11: =IF(D11<>"",IFERROR(INDEX(Produtos!$C$4:$C$4996,MATCH(D11,Produtos!$B$4:$B$4996,0)),"Produto não encontrado"),"") -> TUBO PEAD ESGOTO D 225 | F11: 60
A12: =IF(C12="Entrada",2,IF(C12="Saída",1,".")) -> 2 | B12: 46063 | C12: Entrada | D12: P009 | E12: =IF(D12<>"",IFERROR(INDEX(Produtos!$C$4:$C$4996,MATCH(D12,Produtos!$B$4:$B$4996,0)),"Produto não encontrado"),"") -> TUBO PEAD ESGOTO D 450 | F12: 30
A13: =IF(C13="Entrada",2,IF(C13="Saída",1,".")) -> 2 | B13: 46063 | C13: Entrada | D13: P010 | E13: =IF(D13<>"",IFERROR(INDEX(Produtos!$C$4:$C$4996,MATCH(D13,Produtos!$B$4:$B$4996,0)),"Produto não encontrado"),"") -> TUBO CURRUGADO ESGOTO DN 300 | F13: 193
A14: =IF(C14="Entrada",2,IF(C14="Saída",1,".")) -> 2 | B14: 46063 | C14: Entrada | D14: P011 | E14: =IF(D14<>"",IFERROR(INDEX(Produtos!$C$4:$C$4996,MATCH(D14,Produtos!$B$4:$B$4996,0)),"Produto não encontrado"),"") -> TUBO ESGOTO PVC DN 300 | F14: 321
A15: =IF(C15="Entrada",2,IF(C15="Saída",1,".")) -> 2 | B15: 46063 | C15: Entrada | D15: P012 | E15: =IF(D15<>"",IFERROR(INDEX(Produtos!$C$4:$C$4996,MATCH(D15,Produtos!$B$4:$B$4996,0)),"Produto não encontrado"),"") -> TUBO ESGOTO PVC DN 200 | F15: 348
... A19: =IF(C19="Entrada",2,IF(C19="Saída",1,".")) -> 2 | B19: 46063 | C19: Entrada | D19: P016 | E19: =IF(D19<>"",IFERROR(INDEX(Produtos!$C$4:$C$4996,MATCH(D19,Produtos!$B$4:$B$4996,0)),"Produto não encontrado"),"") -> BLOCO DE PV | F19: 800
A20: =IF(C20="Entrada",2,IF(C20="Saída",1,".")) -> 2 | B20: 46063 | C20: Entrada | D20: P001 | E20: =IF(D20<>"",IFERROR(INDEX(Produtos!$C$4:$C$4996,MATCH(D20,Produtos!$B$4:$B$4996,0)),"Produto não encontrado"),"") -> ADUELA DE 1000 | F20: 40 | G20: GUARANI
A21: =IF(C21="Entrada",2,IF(C21="Saída",1,".")) -> 2 | B21: 46063 | C21: Entrada | D21: P005 | E21: =IF(D21<>"",IFERROR(INDEX(Produtos!$C$4:$C$4996,MATCH(D21,Produtos!$B$4:$B$4996,0)),"Produto não encontrado"),"") -> LAJE SURPERIOR DE 1000 | F21: 90
A22: =IF(C22="Entrada",2,IF(C22="Saída",1,".")) -> 2 | B22: 46063 | C22: Entrada | D22: P003 | E22: =IF(D22<>"",IFERROR(INDEX(Produtos!$C$4:$C$4996,MATCH(D22,Produtos!$B$4:$B$4996,0)),"Produto não encontrado"),"") -> LAJE INFERIOR DE 1000 | F22: 30
A23: =IF(C23="Entrada",2,IF(C23="Saída",1,".")) -> 1 | B23: 46048 | C23: Saída | D23: P001 | E23: =IF(D23<>"",IFERROR(INDEX(Produtos!$C$4:$C$4996,MATCH(D23,Produtos!$B$4:$B$4996,0)),"Produto não encontrado"),"") -> ADUELA DE 1000 | F23: 6 | G23: FABIO
A24: =IF(C24="Entrada",2,IF(C24="Saída",1,".")) -> 1 | B24: 46049 | C24: Saída | D24: P003 | E24: =IF(D24<>"",IFERROR(INDEX(Produtos!$C$4:$C$4996,MATCH(D24,Produtos!$B$4:$B$4996,0)),"Produto não encontrado"),"") -> LAJE INFERIOR DE 1000 | F24: 4 | G24: FABIO
A25: =IF(C25="Entrada",2,IF(C25="Saída",1,".")) -> 1 | B25: 46049 | C25: Saída | D25: P003 | E25: =IF(D25<>"",IFERROR(INDEX(Produtos!$C$4:$C$4996,MATCH(D25,Produtos!$B$4:$B$4996,0)),"Produto não encontrado"),"") -> LAJE INFERIOR DE 1000 | F25: 1 | G25: MARCELO
A26: =IF(C26="Entrada",2,IF(C26="Saída",1,".")) -> 1 | B26: 46049 | C26: Saída | D26: P003 | E26: =IF(D26<>"",IFERROR(INDEX(Produtos!$C$4:$C$4996,MATCH(D26,Produtos!$B$4:$B$4996,0)),"Produto não encontrado"),"") -> LAJE INFERIOR DE 1000 | F26: 1 | G26: EDIVALDO
A27: =IF(C27="Entrada",2,IF(C27="Saída",1,".")) -> 1 | B27: 46049 | C27: Saída | D27: P016 | E27: =IF(D27<>"",IFERROR(INDEX(Produtos!$C$4:$C$4996,MATCH(D27,Produtos!$B$4:$B$4996,0)),"Produto não encontrado"),"") -> BLOCO DE PV | F27: 30 | G27: FABIO
A28: =IF(C28="Entrada",2,IF(C28="Saída",1,".")) -> 1 | B28: 46049 | C28: Saída | D28: P016 | E28: =IF(D28<>"",IFERROR(INDEX(Produtos!$C$4:$C$4996,MATCH(D28,Produtos!$B$4:$B$4996,0)),"Produto não encontrado"),"") -> BLOCO DE PV | F28: 24 | G28: CERSAR
A29: =IF(C29="Entrada",2,IF(C29="Saída",1,".")) -> 1 | B29: 46049 | C29: Saída | D29: P006 | E29: =IF(D29<>"",IFERROR(INDEX(Produtos!$C$4:$C$4996,MATCH(D29,Produtos!$B$4:$B$4996,0)),"Produto não encontrado"),"") -> TUBO PEAD ESGOTO D 355 | F29: 14 | G29: LEANDRO
A30: =IF(C30="Entrada",2,IF(C30="Saída",1,".")) -> 1 | B30: 46049 | C30: Saída | D30: P003 | E30: =IF(D30<>"",IFERROR(INDEX(Produtos!$C$4:$C$4996,MATCH(D30,Produtos!$B$4:$B$4996,0)),"Produto não encontrado"),"") -> LAJE INFERIOR DE 1000 | F30: 1 | G30: PAULINHO
A31: =IF(C31="Entrada",2,IF(C31="Saída",1,".")) -> 1 | B31: 46049 | C31: Saída | D31: P005 | E31: =IF(D31<>"",IFERROR(INDEX(Produtos!$C$4:$C$4996,MATCH(D31,Produtos!$B$4:$B$4996,0)),"Produto não encontrado"),"") -> LAJE SURPERIOR DE 1000 | F31: 2 | G31: PAULINHO
A32: =IF(C32="Entrada",2,IF(C32="Saída",1,".")) -> 1 | B32: 46049 | C32: Saída | D32: P016 | E32: =IF(D32<>"",IFERROR(INDEX(Produtos!$C$4:$C$4996,MATCH(D32,Produtos!$B$4:$B$4996,0)),"Produto não encontrado"),"") -> BLOCO DE PV | F32: 22 | G32: PAULINHO
A33: =IF(C33="Entrada",2,IF(C33="Saída",1,".")) -> 1 | B33: 46049 | C33: Saída | D33: P012 | E33: =IF(D33<>"",IFERROR(INDEX(Produtos!$C$4:$C$4996,MATCH(D33,Produtos!$B$4:$B$4996,0)),"Produto não encontrado"),"") -> TUBO ESGOTO PVC DN 200 | F33: 1 | G33: PAULINHO
A34: =IF(C34="Entrada",2,IF(C34="Saída",1,".")) -> 1 | B34: 46050 | C34: Saída | D34: P001 | E34: =IF(D34<>"",IFERROR(INDEX(Produtos!$C$4:$C$4996,MATCH(D34,Produtos!$B$4:$B$4996,0)),"Produto não encontrado"),"") -> ADUELA DE 1000 | F34: 2 | G34: WALTER
... A88: =IF(C88="Entrada",2,IF(C88="Saída",1,".")) -> 1 | B88: 46057 | C88: Saída | D88: P002 | E88: =IF(D88<>"",IFERROR(INDEX(Produtos!$C$4:$C$4996,MATCH(D88,Produtos!$B$4:$B$4996,0)),"Produto não encontrado"),"") -> ADUELA DE 600 | F88: 1 | G88: JONATHAN
A89: =IF(C89="Entrada",2,IF(C89="Saída",1,".")) -> 1 | B89: 46057 | C89: Saída | D89: P002 | E89: =IF(D89<>"",IFERROR(INDEX(Produtos!$C$4:$C$4996,MATCH(D89,Produtos!$B$4:$B$4996,0)),"Produto não encontrado"),"") -> ADUELA DE 600 | F89: 60 | G89: LUCIANO | H89: PERFORMANCE
A90: =IF(C90="Entrada",2,IF(C90="Saída",1,".")) -> 1 | B90: 46057 | C90: Saída | D90: P001 | E90: =IF(D90<>"",IFERROR(INDEX(Produtos!$C$4:$C$4996,MATCH(D90,Produtos!$B$4:$B$4996,0)),"Produto não encontrado"),"") -> ADUELA DE 1000 | F90: 1 | G90: PAULINHO
A91: =IF(C91="Entrada",2,IF(C91="Saída",1,".")) -> 1 | B91: 46057 | C91: Saída | D91: P001 | E91: =IF(D91<>"",IFERROR(INDEX(Produtos!$C$4:$C$4996,MATCH(D91,Produtos!$B$4:$B$4996,0)),"Produto não encontrado"),"") -> ADUELA DE 1000 | F91: 2 | G91: CARLOS
A92: =IF(C92="Entrada",2,IF(C92="Saída",1,".")) -> 1 | B92: 46057 | C92: Saída | D92: P003 | E92: =IF(D92<>"",IFERROR(INDEX(Produtos!$C$4:$C$4996,MATCH(D92,Produtos!$B$4:$B$4996,0)),"Produto não encontrado"),"") -> LAJE INFERIOR DE 1000 | F92: 2 | G92: CARLOS
A93: =IF(C93="Entrada",2,IF(C93="Saída",1,".")) -> 1 | B93: 46057 | C93: Saída | D93: P005 | E93: =IF(D93<>"",IFERROR(INDEX(Produtos!$C$4:$C$4996,MATCH(D93,Produtos!$B$4:$B$4996,0)),"Produto não encontrado"),"") -> LAJE SURPERIOR DE 1000 | F93: 1 | G93: CARLOS
A94: =IF(C94="Entrada",2,IF(C94="Saída",1,".")) -> 1 | B94: 46057 | C94: Saída | D94: P001 | E94: =IF(D94<>"",IFERROR(INDEX(Produtos!$C$4:$C$4996,MATCH(D94,Produtos!$B$4:$B$4996,0)),"Produto não encontrado"),"") -> ADUELA DE 1000 | F94: 1 | G94: CARLOS
A95: =IF(C95="Entrada",2,IF(C95="Saída",1,".")) -> 1 | B95: 46057 | C95: Saída | D95: P001 | E95: =IF(D95<>"",IFERROR(INDEX(Produtos!$C$4:$C$4996,MATCH(D95,Produtos!$B$4:$B$4996,0)),"Produto não encontrado"),"") -> ADUELA DE 1000 | F95: 1 | G95: IGOR
A96: =IF(C96="Entrada",2,IF(C96="Saída",1,".")) -> 1 | B96: 46058 | C96: Saída | D96: P001 | E96: =IF(D96<>"",IFERROR(INDEX(Produtos!$C$4:$C$4996,MATCH(D96,Produtos!$B$4:$B$4996,0)),"Produto não encontrado"),"") -> ADUELA DE 1000 | F96: 1 | G96: CARLOS
A97: =IF(C97="Entrada",2,IF(C97="Saída",1,".")) -> 1 | B97: 46058 | C97: Saída | D97: P002 | E97: =IF(D97<>"",IFERROR(INDEX(Produtos!$C$4:$C$4996,MATCH(D97,Produtos!$B$4:$B$4996,0)),"Produto não encontrado"),"") -> ADUELA DE 600 | F97: 1 | G97: CARLOS
...

Sheet Resumo
B1: RESUMO
B3: TOTAL DE PRODUTOS | E3: TOTAL DE PRODUTOS COM SALDO DISPONÍVEL | H3: TOTAL DE PRODUTOS COM SALDO ABAIXO DO MÍNIMO | K3: TOTAL DE PRODUTOS COM SALDO ZERADO
B4: =COUNTA(Produtos!$C$4:$C$4996) -> 28 | E4: =COUNTIF(Produtos!$F$4:$F$4996,"Saldo disponível") -> 21 | H4: =COUNTIF(Produtos!$F$4:$F$4996,"Saldo abaixo do mínimo") -> 7 | K4: =COUNTIF(Produtos!$F$4:$F$4996,"Saldo zerado") -> 0
B6: GRÁFICO DE ENTRADAS X SAÍDAS POR PERÍODO | L6: 2026
C8: Janeiro | F8: =SUMIFS(Movimentos!$F$4:$F$9996,Movimentos!$B$4:$B$9996,">="&DATE($L$6,MONTH(1&C8),1),Movimentos!$B$4:$B$9996,"<="&EOMONTH(DATE($L$6,MONTH(1&C8),1),0),Movimentos!$C$4:$C$9996,"Entrada") -> 0 | I8: =SUMIFS(Movimentos!$F$4:$F$9996,Movimentos!$B$4:$B$9996,">="&DATE($L$6,MONTH(1&C8),1),Movimentos!$B$4:$B$9996,"<="&EOMONTH(DATE($L$6,MONTH(1&C8),1),0),Movimentos!$C$4:$C$9996,"Saída") -> 263
C9: Fevereiro | F9: =SUMIFS(Movimentos!$F$4:$F$9996,Movimentos!$B$4:$B$9996,">="&DATE($L$6,MONTH(1&C9),1),Movimentos!$B$4:$B$9996,"<="&EOMONTH(DATE($L$6,MONTH(1&C9),1),0),Movimentos!$C$4:$C$9996,"Entrada") -> 5478 | I9: =SUMIFS(Movimentos!$F$4:$F$9996,Movimentos!$B$4:$B$9996,">="&DATE($L$6,MONTH(1&C9),1),Movimentos!$B$4:$B$9996,"<="&EOMONTH(DATE($L$6,MONTH(1&C9),1),0),Movimentos!$C$4:$C$9996,"Saída") -> 1972
C10: Março | F10: =SUMIFS(Movimentos!$F$4:$F$9996,Movimentos!$B$4:$B$9996,">="&DATE($L$6,MONTH(1&C10),1),Movimentos!$B$4:$B$9996,"<="&EOMONTH(DATE($L$6,MONTH(1&C10),1),0),Movimentos!$C$4:$C$9996,"Entrada") -> 109921 | I10: =SUMIFS(Movimentos!$F$4:$F$9996,Movimentos!$B$4:$B$9996,">="&DATE($L$6,MONTH(1&C10),1),Movimentos!$B$4:$B$9996,"<="&EOMONTH(DATE($L$6,MONTH(1&C10),1),0),Movimentos!$C$4:$C$9996,"Saída") -> 13582
C11: Abril | F11: =SUMIFS(Movimentos!$F$4:$F$9996,Movimentos!$B$4:$B$9996,">="&DATE($L$6,MONTH(1&C11),1),Movimentos!$B$4:$B$9996,"<="&EOMONTH(DATE($L$6,MONTH(1&C11),1),0),Movimentos!$C$4:$C$9996,"Entrada") -> 3212 | I11: =SUMIFS(Movimentos!$F$4:$F$9996,Movimentos!$B$4:$B$9996,">="&DATE($L$6,MONTH(1&C11),1),Movimentos!$B$4:$B$9996,"<="&EOMONTH(DATE($L$6,MONTH(1&C11),1),0),Movimentos!$C$4:$C$9996,"Saída") -> 15170
C12: Maio | F12: =SUMIFS(Movimentos!$F$4:$F$9996,Movimentos!$B$4:$B$9996,">="&DATE($L$6,MONTH(1&C12),1),Movimentos!$B$4:$B$9996,"<="&EOMONTH(DATE($L$6,MONTH(1&C12),1),0),Movimentos!$C$4:$C$9996,"Entrada") -> 0 | I12: =SUMIFS(Movimentos!$F$4:$F$9996,Movimentos!$B$4:$B$9996,">="&DATE($L$6,MONTH(1&C12),1),Movimentos!$B$4:$B$9996,"<="&EOMONTH(DATE($L$6,MONTH(1&C12),1),0),Movimentos!$C$4:$C$9996,"Saída") -> 0
C13: Junho | F13: =SUMIFS(Movimentos!$F$4:$F$9996,Movimentos!$B$4:$B$9996,">="&DATE($L$6,MONTH(1&C13),1),Movimentos!$B$4:$B$9996,"<="&EOMONTH(DATE($L$6,MONTH(1&C13),1),0),Movimentos!$C$4:$C$9996,"Entrada") -> 0 | I13: =SUMIFS(Movimentos!$F$4:$F$9996,Movimentos!$B$4:$B$9996,">="&DATE($L$6,MONTH(1&C13),1),Movimentos!$B$4:$B$9996,"<="&EOMONTH(DATE($L$6,MONTH(1&C13),1),0),Movimentos!$C$4:$C$9996,"Saída") -> 0
C14: Julho | F14: =SUMIFS(Movimentos!$F$4:$F$9996,Movimentos!$B$4:$B$9996,">="&DATE($L$6,MONTH(1&C14),1),Movimentos!$B$4:$B$9996,"<="&EOMONTH(DATE($L$6,MONTH(1&C14),1),0),Movimentos!$C$4:$C$9996,"Entrada") -> 0 | I14: =SUMIFS(Movimentos!$F$4:$F$9996,Movimentos!$B$4:$B$9996,">="&DATE($L$6,MONTH(1&C14),1),Movimentos!$B$4:$B$9996,"<="&EOMONTH(DATE($L$6,MONTH(1&C14),1),0),Movimentos!$C$4:$C$9996,"Saída") -> 0
C15: Agosto | F15: =SUMIFS(Movimentos!$F$4:$F$9996,Movimentos!$B$4:$B$9996,">="&DATE($L$6,MONTH(1&C15),1),Movimentos!$B$4:$B$9996,"<="&EOMONTH(DATE($L$6,MONTH(1&C15),1),0),Movimentos!$C$4:$C$9996,"Entrada") -> 0 | I15: =SUMIFS(Movimentos!$F$4:$F$9996,Movimentos!$B$4:$B$9996,">="&DATE($L$6,MONTH(1&C15),1),Movimentos!$B$4:$B$9996,"<="&EOMONTH(DATE($L$6,MONTH(1&C15),1),0),Movimentos!$C$4:$C$9996,"Saída") -> 0
C16: Setembro | F16: =SUMIFS(Movimentos!$F$4:$F$9996,Movimentos!$B$4:$B$9996,">="&DATE($L$6,MONTH(1&C16),1),Movimentos!$B$4:$B$9996,"<="&EOMONTH(DATE($L$6,MONTH(1&C16),1),0),Movimentos!$C$4:$C$9996,"Entrada") -> 0 | I16: =SUMIFS(Movimentos!$F$4:$F$9996,Movimentos!$B$4:$B$9996,">="&DATE($L$6,MONTH(1&C16),1),Movimentos!$B$4:$B$9996,"<="&EOMONTH(DATE($L$6,MONTH(1&C16),1),0),Movimentos!$C$4:$C$9996,"Saída") -> 0
C17: Outubro | F17: =SUMIFS(Movimentos!$F$4:$F$9996,Movimentos!$B$4:$B$9996,">="&DATE($L$6,MONTH(1&C17),1),Movimentos!$B$4:$B$9996,"<="&EOMONTH(DATE($L$6,MONTH(1&C17),1),0),Movimentos!$C$4:$C$9996,"Entrada") -> 0 | I17: =SUMIFS(Movimentos!$F$4:$F$9996,Movimentos!$B$4:$B$9996,">="&DATE($L$6,MONTH(1&C17),1),Movimentos!$B$4:$B$9996,"<="&EOMONTH(DATE($L$6,MONTH(1&C17),1),0),Movimentos!$C$4:$C$9996,"Saída") -> 0
C18: Novembro | F18: =SUMIFS(Movimentos!$F$4:$F$9996,Movimentos!$B$4:$B$9996,">="&DATE($L$6,MONTH(1&C18),1),Movimentos!$B$4:$B$9996,"<="&EOMONTH(DATE($L$6,MONTH(1&C18),1),0),Movimentos!$C$4:$C$9996,"Entrada") -> 0 | I18: =SUMIFS(Movimentos!$F$4:$F$9996,Movimentos!$B$4:$B$9996,">="&DATE($L$6,MONTH(1&C18),1),Movimentos!$B$4:$B$9996,"<="&EOMONTH(DATE($L$6,MONTH(1&C18),1),0),Movimentos!$C$4:$C$9996,"Saída") -> 0
C19: Dezembro | F19: =SUMIFS(Movimentos!$F$4:$F$9996,Movimentos!$B$4:$B$9996,">="&DATE($L$6,MONTH(1&C19),1),Movimentos!$B$4:$B$9996,"<="&EOMONTH(DATE($L$6,MONTH(1&C19),1),0),Movimentos!$C$4:$C$9996,"Entrada") -> 0 | I19: =SUMIFS(Movimentos!$F$4:$F$9996,Movimentos!$B$4:$B$9996,">="&DATE($L$6,MONTH(1&C19),1),Movimentos!$B$4:$B$9996,"<="&EOMONTH(DATE($L$6,MONTH(1&C19),1),0),Movimentos!$C$4:$C$9996,"Saída") -> 0
B22: CONSULTAR PRODUTO
B24: Cód Produto: | C24: P006 | E24: Situação: | F24: =IF($C$24<>"",IFERROR(INDEX(Produtos!$F$4:$F$4996,MATCH($C$24,Produtos!$B$4:$B$4996,0)),"Produto não encontrado"),"") -> Saldo disponível
B26: Descrição: | C26: =IF($C$24<>"",IFERROR(INDEX(Produtos!$C$4:$C$4996,MATCH($C$24,Produtos!$B$4:$B$4996,0)),"Produto não encontrado"),"") -> TUBO PEAD ESGOTO D 355 | H26: Saldo Atual: | I26: =IF($C$24<>"",IFERROR(INDEX(Produtos!$E$4:$E$4996,MATCH($C$24,Produtos!$B$4:$B$4996,0)),""),"") -> 389
B28: Entradas: | C28: =IF($C$24<>"",SUMIFS(Movimentos!$F$4:$F$9996,Movimentos!$D$4:$D$9996,$C$24,Movimentos!$C$4:$C$9996,"Entrada"),"") -> 1096 | E28: Saídas: | F28: =IF($C$24<>"",SUMIFS(Movimentos!$F$4:$F$9996,Movimentos!$D$4:$D$9996,$C$24,Movimentos!$C$4:$C$9996,"Saída"),"") -> 707 | H28: Estoque Mínimo: | I28: =IF($C$24<>"",IFERROR(INDEX(Produtos!$D$4:$D$4996,MATCH($C$24,Produtos!$B$4:$B$4996,0)),""),"") -> 200
B30: GRÁFICO DE ENTRADAS X SAÍDAS DO PROTUDO POR PERÍODO | L30: 2026
C32: Janeiro | F32: =SUMIFS(Movimentos!$F$4:$F$9996,Movimentos!$B$4:$B$9996,">="&DATE($L$30,MONTH(1&C32),1),Movimentos!$B$4:$B$9996,"<="&EOMONTH(DATE($L$30,MONTH(1&C32),1),0),Movimentos!$D$4:$D$9996,$C$24,Movimentos!$C$4:$C$9996,"Entrada") -> 0 | I32: =SUMIFS(Movimentos!$F$4:$F$9996,Movimentos!$B$4:$B$9996,">="&DATE($L$30,MONTH(1&C32),1),Movimentos!$B$4:$B$9996,"<="&EOMONTH(DATE($L$30,MONTH(1&C32),1),0),Movimentos!$D$4:$D$9996,$C$24,Movimentos!$C$4:$C$9996,"Saída") -> 95
C33: Fevereiro | F33: =SUMIFS(Movimentos!$F$4:$F$9996,Movimentos!$B$4:$B$9996,">="&DATE($L$30,MONTH(1&C33),1),Movimentos!$B$4:$B$9996,"<="&EOMONTH(DATE($L$30,MONTH(1&C33),1),0),Movimentos!$D$4:$D$9996,$C$24,Movimentos!$C$4:$C$9996,"Entrada") -> 1096 | I33: =SUMIFS(Movimentos!$F$4:$F$9996,Movimentos!$B$4:$B$9996,">="&DATE($L$30,MONTH(1&C33),1),Movimentos!$B$4:$B$9996,"<="&EOMONTH(DATE($L$30,MONTH(1&C33),1),0),Movimentos!$D$4:$D$9996,$C$24,Movimentos!$C$4:$C$9996,"Saída") -> 275
C34: Março | F34: =SUMIFS(Movimentos!$F$4:$F$9996,Movimentos!$B$4:$B$9996,">="&DATE($L$30,MONTH(1&C34),1),Movimentos!$B$4:$B$9996,"<="&EOMONTH(DATE($L$30,MONTH(1&C34),1),0),Movimentos!$D$4:$D$9996,$C$24,Movimentos!$C$4:$C$9996,"Entrada") -> 0 | I34: =SUMIFS(Movimentos!$F$4:$F$9996,Movimentos!$B$4:$B$9996,">="&DATE($L$30,MONTH(1&C34),1),Movimentos!$B$4:$B$9996,"<="&EOMONTH(DATE($L$30,MONTH(1&C34),1),0),Movimentos!$D$4:$D$9996,$C$24,Movimentos!$C$4:$C$9996,"Saída") -> 237
C35: Abril | F35: =SUMIFS(Movimentos!$F$4:$F$9996,Movimentos!$B$4:$B$9996,">="&DATE($L$30,MONTH(1&C35),1),Movimentos!$B$4:$B$9996,"<="&EOMONTH(DATE($L$30,MONTH(1&C35),1),0),Movimentos!$D$4:$D$9996,$C$24,Movimentos!$C$4:$C$9996,"Entrada") -> 0 | I35: =SUMIFS(Movimentos!$F$4:$F$9996,Movimentos!$B$4:$B$9996,">="&DATE($L$30,MONTH(1&C35),1),Movimentos!$B$4:$B$9996,"<="&EOMONTH(DATE($L$30,MONTH(1&C35),1),0),Movimentos!$D$4:$D$9996,$C$24,Movimentos!$C$4:$C$9996,"Saída") -> 100
C36: Maio | F36: =SUMIFS(Movimentos!$F$4:$F$9996,Movimentos!$B$4:$B$9996,">="&DATE($L$30,MONTH(1&C36),1),Movimentos!$B$4:$B$9996,"<="&EOMONTH(DATE($L$30,MONTH(1&C36),1),0),Movimentos!$D$4:$D$9996,$C$24,Movimentos!$C$4:$C$9996,"Entrada") -> 0 | I36: =SUMIFS(Movimentos!$F$4:$F$9996,Movimentos!$B$4:$B$9996,">="&DATE($L$30,MONTH(1&C36),1),Movimentos!$B$4:$B$9996,"<="&EOMONTH(DATE($L$30,MONTH(1&C36),1),0),Movimentos!$D$4:$D$9996,$C$24,Movimentos!$C$4:$C$9996,"Saída") -> 0
C37: Junho | F37: =SUMIFS(Movimentos!$F$4:$F$9996,Movimentos!$B$4:$B$9996,">="&DATE($L$30,MONTH(1&C37),1),Movimentos!$B$4:$B$9996,"<="&EOMONTH(DATE($L$30,MONTH(1&C37),1),0),Movimentos!$D$4:$D$9996,$C$24,Movimentos!$C$4:$C$9996,"Entrada") -> 0 | I37: =SUMIFS(Movimentos!$F$4:$F$9996,Movimentos!$B$4:$B$9996,">="&DATE($L$30,MONTH(1&C37),1),Movimentos!$B$4:$B$9996,"<="&EOMONTH(DATE($L$30,MONTH(1&C37),1),0),Movimentos!$D$4:$D$9996,$C$24,Movimentos!$C$4:$C$9996,"Saída") -> 0
C38: Julho | F38: =SUMIFS(Movimentos!$F$4:$F$9996,Movimentos!$B$4:$B$9996,">="&DATE($L$30,MONTH(1&C38),1),Movimentos!$B$4:$B$9996,"<="&EOMONTH(DATE($L$30,MONTH(1&C38),1),0),Movimentos!$D$4:$D$9996,$C$24,Movimentos!$C$4:$C$9996,"Entrada") -> 0 | I38: =SUMIFS(Movimentos!$F$4:$F$9996,Movimentos!$B$4:$B$9996,">="&DATE($L$30,MONTH(1&C38),1),Movimentos!$B$4:$B$9996,"<="&EOMONTH(DATE($L$30,MONTH(1&C38),1),0),Movimentos!$D$4:$D$9996,$C$24,Movimentos!$C$4:$C$9996,"Saída") -> 0
C39: Agosto | F39: =SUMIFS(Movimentos!$F$4:$F$9996,Movimentos!$B$4:$B$9996,">="&DATE($L$30,MONTH(1&C39),1),Movimentos!$B$4:$B$9996,"<="&EOMONTH(DATE($L$30,MONTH(1&C39),1),0),Movimentos!$D$4:$D$9996,$C$24,Movimentos!$C$4:$C$9996,"Entrada") -> 0 | I39: =SUMIFS(Movimentos!$F$4:$F$9996,Movimentos!$B$4:$B$9996,">="&DATE($L$30,MONTH(1&C39),1),Movimentos!$B$4:$B$9996,"<="&EOMONTH(DATE($L$30,MONTH(1&C39),1),0),Movimentos!$D$4:$D$9996,$C$24,Movimentos!$C$4:$C$9996,"Saída") -> 0
C40: Setembro | F40: =SUMIFS(Movimentos!$F$4:$F$9996,Movimentos!$B$4:$B$9996,">="&DATE($L$30,MONTH(1&C40),1),Movimentos!$B$4:$B$9996,"<="&EOMONTH(DATE($L$30,MONTH(1&C40),1),0),Movimentos!$D$4:$D$9996,$C$24,Movimentos!$C$4:$C$9996,"Entrada") -> 0 | I40: =SUMIFS(Movimentos!$F$4:$F$9996,Movimentos!$B$4:$B$9996,">="&DATE($L$30,MONTH(1&C40),1),Movimentos!$B$4:$B$9996,"<="&EOMONTH(DATE($L$30,MONTH(1&C40),1),0),Movimentos!$D$4:$D$9996,$C$24,Movimentos!$C$4:$C$9996,"Saída") -> 0
C41: Outubro | F41: =SUMIFS(Movimentos!$F$4:$F$9996,Movimentos!$B$4:$B$9996,">="&DATE($L$30,MONTH(1&C41),1),Movimentos!$B$4:$B$9996,"<="&EOMONTH(DATE($L$30,MONTH(1&C41),1),0),Movimentos!$D$4:$D$9996,$C$24,Movimentos!$C$4:$C$9996,"Entrada") -> 0 | I41: =SUMIFS(Movimentos!$F$4:$F$9996,Movimentos!$B$4:$B$9996,">="&DATE($L$30,MONTH(1&C41),1),Movimentos!$B$4:$B$9996,"<="&EOMONTH(DATE($L$30,MONTH(1&C41),1),0),Movimentos!$D$4:$D$9996,$C$24,Movimentos!$C$4:$C$9996,"Saída") -> 0
C42: Novembro | F42: =SUMIFS(Movimentos!$F$4:$F$9996,Movimentos!$B$4:$B$9996,">="&DATE($L$30,MONTH(1&C42),1),Movimentos!$B$4:$B$9996,"<="&EOMONTH(DATE($L$30,MONTH(1&C42),1),0),Movimentos!$D$4:$D$9996,$C$24,Movimentos!$C$4:$C$9996,"Entrada") -> 0 | I42: =SUMIFS(Movimentos!$F$4:$F$9996,Movimentos!$B$4:$B$9996,">="&DATE($L$30,MONTH(1&C42),1),Movimentos!$B$4:$B$9996,"<="&EOMONTH(DATE($L$30,MONTH(1&C42),1),0),Movimentos!$D$4:$D$9996,$C$24,Movimentos!$C$4:$C$9996,"Saída") -> 0
C43: Dezembro | F43: =SUMIFS(Movimentos!$F$4:$F$9996,Movimentos!$B$4:$B$9996,">="&DATE($L$30,MONTH(1&C43),1),Movimentos!$B$4:$B$9996,"<="&EOMONTH(DATE($L$30,MONTH(1&C43),1),0),Movimentos!$D$4:$D$9996,$C$24,Movimentos!$C$4:$C$9996,"Entrada") -> 0 | I43: =SUMIFS(Movimentos!$F$4:$F$9996,Movimentos!$B$4:$B$9996,">="&DATE($L$30,MONTH(1&C43),1),Movimentos!$B$4:$B$9996,"<="&EOMONTH(DATE($L$30,MONTH(1&C43),1),0),Movimentos!$D$4:$D$9996,$C$24,Movimentos!$C$4:$C$9996,"Saída") -> 0
