Workbook

Sheet PDS_Lancamentos
A1: PDS Integra 6A - Base consolidada (Word)
A2: Arquivos consolidados: Abril, Dezembro, Fevereiro, Janeiro, Mar?o e Maio | Total de linhas extra?das: 2206
A4: Data | B4: Dia_Semana | C4: Obra | D4: Responsavel_Obra | E4: Equipe | F4: Atividade | G4: PV_Inicio | H4: PV_Fim | I4: PV_Texto | J4: Tipo_Atividade | K4: Categoria | L4: Fonte_Arquivo | M4: MES_REF | N4: RUA | O4: NUMERO | P4: MUNICIPIO | Q4: SUBPREFEITURA | R4: METODO_PADRAO | S4: EXTENSAO_M | T4: CHAVE_RELATORIO | U4: OBS_RELATORIO
A5: 45992 | B5: Segunda | C5: Mar de Coral | E5: LS | F5: Escavação mecânica e montagem de armco PV 01 | G5: 01 | I5: 01 | J5: Escavação | K5: Planejamento | L5: PDS-dezembro(1).docx | M5: =IF($A5="","",TEXT($A5,"mmmm/yyyy")) | P5: =IFERROR(_xludf.XLOOKUP($N5,Base_Enderecos!$A:$A,Base_Enderecos!$B:$B,""),"") | Q5: =IFERROR(_xludf.XLOOKUP($N5,Base_Enderecos!$A:$A,Base_Enderecos!$C:$C,""),"") | R5: =IF(OR(ISNUMBER(SEARCH("HDD",$F5)),ISNUMBER(SEARCH("MND",$F5)),ISNUMBER(SEARCH("PEAD",$F5)),ISNUMBER(SEARCH("Puxe",$J5)),ISNUMBER(SEARCH("Apoio HDD",$F5))),"MND",IF(OR(ISNUMBER(SEARCH("VCA",$F5)),ISNUMBER(SEARCH("PVC",$F5)),ISNUMBER(SEARCH("vca",$J5)),ISNUMBER(SEARCH("Transformação",$J5))),"VCA",IF(OR(ISNUMBER(SEARCH("crava",$F5)),ISNUMBER(SEARCH("tubo cravado",$F5)),ISNUMBER(SEARCH("shaft",$J5)),ISNUMBER(SEARCH("concreto",$F5))),"TUBO CRAVADO",""))) | T5: =IF($A5="","",TEXT($A5,"yyyymm")&"|"&$C5&"|"&$F5&"|"&$N5&"|"&$R5)
A6: 45992 | B6: Segunda | C6: Bandeirantes | E6: Daniel (pisos) | F6: Acabamento em piso PV 14 | G6: 14 | I6: 14 | J6: Acabamento | K6: Planejamento | L6: PDS-dezembro(1).docx | M6: =IF($A6="","",TEXT($A6,"mmmm/yyyy")) | P6: =IFERROR(_xludf.XLOOKUP($N6,Base_Enderecos!$A:$A,Base_Enderecos!$B:$B,""),"") | Q6: =IFERROR(_xludf.XLOOKUP($N6,Base_Enderecos!$A:$A,Base_Enderecos!$C:$C,""),"") | R6: =IF(OR(ISNUMBER(SEARCH("HDD",$F6)),ISNUMBER(SEARCH("MND",$F6)),ISNUMBER(SEARCH("PEAD",$F6)),ISNUMBER(SEARCH("Puxe",$J6)),ISNUMBER(SEARCH("Apoio HDD",$F6))),"MND",IF(OR(ISNUMBER(SEARCH("VCA",$F6)),ISNUMBER(SEARCH("PVC",$F6)),ISNUMBER(SEARCH("vca",$J6)),ISNUMBER(SEARCH("Transformação",$J6))),"VCA",IF(OR(ISNUMBER(SEARCH("crava",$F6)),ISNUMBER(SEARCH("tubo cravado",$F6)),ISNUMBER(SEARCH("shaft",$J6)),ISNUMBER(SEARCH("concreto",$F6))),"TUBO CRAVADO",""))) | T6: =IF($A6="","",TEXT($A6,"yyyymm")&"|"&$C6&"|"&$F6&"|"&$N6&"|"&$R6)
A7: 45992 | B7: Segunda | C7: CT Lageado | E7: Marcelo | F7: Transformação PV 1.2 | G7: 1.2 | I7: 1.2 | J7: Transformação | K7: Planejamento | L7: PDS-dezembro(1).docx | M7: =IF($A7="","",TEXT($A7,"mmmm/yyyy")) | P7: =IFERROR(_xludf.XLOOKUP($N7,Base_Enderecos!$A:$A,Base_Enderecos!$B:$B,""),"") | Q7: =IFERROR(_xludf.XLOOKUP($N7,Base_Enderecos!$A:$A,Base_Enderecos!$C:$C,""),"") | R7: =IF(OR(ISNUMBER(SEARCH("HDD",$F7)),ISNUMBER(SEARCH("MND",$F7)),ISNUMBER(SEARCH("PEAD",$F7)),ISNUMBER(SEARCH("Puxe",$J7)),ISNUMBER(SEARCH("Apoio HDD",$F7))),"MND",IF(OR(ISNUMBER(SEARCH("VCA",$F7)),ISNUMBER(SEARCH("PVC",$F7)),ISNUMBER(SEARCH("vca",$J7)),ISNUMBER(SEARCH("Transformação",$J7))),"VCA",IF(OR(ISNUMBER(SEARCH("crava",$F7)),ISNUMBER(SEARCH("tubo cravado",$F7)),ISNUMBER(SEARCH("shaft",$J7)),ISNUMBER(SEARCH("concreto",$F7))),"TUBO CRAVADO",""))) | T7: =IF($A7="","",TEXT($A7,"yyyymm")&"|"&$C7&"|"&$F7&"|"&$N7&"|"&$R7)
A8: 45992 | B8: Segunda | C8: CT Lageado | E8: Higor | F8: Acabamento PV 3.1 | G8: 3.1 | I8: 3.1 | J8: Acabamento | K8: Planejamento | L8: PDS-dezembro(1).docx | M8: =IF($A8="","",TEXT($A8,"mmmm/yyyy")) | P8: =IFERROR(_xludf.XLOOKUP($N8,Base_Enderecos!$A:$A,Base_Enderecos!$B:$B,""),"") | Q8: =IFERROR(_xludf.XLOOKUP($N8,Base_Enderecos!$A:$A,Base_Enderecos!$C:$C,""),"") | R8: =IF(OR(ISNUMBER(SEARCH("HDD",$F8)),ISNUMBER(SEARCH("MND",$F8)),ISNUMBER(SEARCH("PEAD",$F8)),ISNUMBER(SEARCH("Puxe",$J8)),ISNUMBER(SEARCH("Apoio HDD",$F8))),"MND",IF(OR(ISNUMBER(SEARCH("VCA",$F8)),ISNUMBER(SEARCH("PVC",$F8)),ISNUMBER(SEARCH("vca",$J8)),ISNUMBER(SEARCH("Transformação",$J8))),"VCA",IF(OR(ISNUMBER(SEARCH("crava",$F8)),ISNUMBER(SEARCH("tubo cravado",$F8)),ISNUMBER(SEARCH("shaft",$J8)),ISNUMBER(SEARCH("concreto",$F8))),"TUBO CRAVADO",""))) | T8: =IF($A8="","",TEXT($A8,"yyyymm")&"|"&$C8&"|"&$F8&"|"&$N8&"|"&$R8)
A9: 45992 | B9: Segunda | C9: CT Lageado | E9: Natalino | F9: Apoio HDD entre PVs 03 a 05 | G9: 03 | I9: 03 | J9: Apoio HDD | K9: Planejamento | L9: PDS-dezembro(1).docx | M9: =IF($A9="","",TEXT($A9,"mmmm/yyyy")) | P9: =IFERROR(_xludf.XLOOKUP($N9,Base_Enderecos!$A:$A,Base_Enderecos!$B:$B,""),"") | Q9: =IFERROR(_xludf.XLOOKUP($N9,Base_Enderecos!$A:$A,Base_Enderecos!$C:$C,""),"") | R9: =IF(OR(ISNUMBER(SEARCH("HDD",$F9)),ISNUMBER(SEARCH("MND",$F9)),ISNUMBER(SEARCH("PEAD",$F9)),ISNUMBER(SEARCH("Puxe",$J9)),ISNUMBER(SEARCH("Apoio HDD",$F9))),"MND",IF(OR(ISNUMBER(SEARCH("VCA",$F9)),ISNUMBER(SEARCH("PVC",$F9)),ISNUMBER(SEARCH("vca",$J9)),ISNUMBER(SEARCH("Transformação",$J9))),"VCA",IF(OR(ISNUMBER(SEARCH("crava",$F9)),ISNUMBER(SEARCH("tubo cravado",$F9)),ISNUMBER(SEARCH("shaft",$J9)),ISNUMBER(SEARCH("concreto",$F9))),"TUBO CRAVADO",""))) | T9: =IF($A9="","",TEXT($A9,"yyyymm")&"|"&$C9&"|"&$F9&"|"&$N9&"|"&$R9)
A10: 45992 | B10: Segunda | C10: CT Lageado | E10: WJ (Edson) | F10: Execução do furo piloto entre os PVs 03 ao 05 | G10: 03 | I10: 03 | J10: Furo piloto | K10: Planejamento | L10: PDS-dezembro(1).docx | M10: =IF($A10="","",TEXT($A10,"mmmm/yyyy")) | P10: =IFERROR(_xludf.XLOOKUP($N10,Base_Enderecos!$A:$A,Base_Enderecos!$B:$B,""),"") | Q10: =IFERROR(_xludf.XLOOKUP($N10,Base_Enderecos!$A:$A,Base_Enderecos!$C:$C,""),"") | R10: =IF(OR(ISNUMBER(SEARCH("HDD",$F10)),ISNUMBER(SEARCH("MND",$F10)),ISNUMBER(SEARCH("PEAD",$F10)),ISNUMBER(SEARCH("Puxe",$J10)),ISNUMBER(SEARCH("Apoio HDD",$F10))),"MND",IF(OR(ISNUMBER(SEARCH("VCA",$F10)),ISNUMBER(SEARCH("PVC",$F10)),ISNUMBER(SEARCH("vca",$J10)),ISNUMBER(SEARCH("Transformação",$J10))),"VCA",IF(OR(ISNUMBER(SEARCH("crava",$F10)),ISNUMBER(SEARCH("tubo cravado",$F10)),ISNUMBER(SEARCH("shaft",$J10)),ISNUMBER(SEARCH("concreto",$F10))),"TUBO CRAVADO",""))) | T10: =IF($A10="","",TEXT($A10,"yyyymm")&"|"&$C10&"|"&$F10&"|"&$N10&"|"&$R10)
A11: 45992 | B11: Segunda | C11: CT Lageado | E11: Fabrício | F11: Apoio HDD entre PVs 04 a 4.1 | G11: 04 | I11: 04 | J11: Apoio HDD | K11: Planejamento | L11: PDS-dezembro(1).docx | M11: =IF($A11="","",TEXT($A11,"mmmm/yyyy")) | P11: =IFERROR(_xludf.XLOOKUP($N11,Base_Enderecos!$A:$A,Base_Enderecos!$B:$B,""),"") | Q11: =IFERROR(_xludf.XLOOKUP($N11,Base_Enderecos!$A:$A,Base_Enderecos!$C:$C,""),"") | R11: =IF(OR(ISNUMBER(SEARCH("HDD",$F11)),ISNUMBER(SEARCH("MND",$F11)),ISNUMBER(SEARCH("PEAD",$F11)),ISNUMBER(SEARCH("Puxe",$J11)),ISNUMBER(SEARCH("Apoio HDD",$F11))),"MND",IF(OR(ISNUMBER(SEARCH("VCA",$F11)),ISNUMBER(SEARCH("PVC",$F11)),ISNUMBER(SEARCH("vca",$J11)),ISNUMBER(SEARCH("Transformação",$J11))),"VCA",IF(OR(ISNUMBER(SEARCH("crava",$F11)),ISNUMBER(SEARCH("tubo cravado",$F11)),ISNUMBER(SEARCH("shaft",$J11)),ISNUMBER(SEARCH("concreto",$F11))),"TUBO CRAVADO",""))) | T11: =IF($A11="","",TEXT($A11,"yyyymm")&"|"&$C11&"|"&$F11&"|"&$N11&"|"&$R11)
A12: 45992 | B12: Segunda | C12: CT Lageado | E12: Work Drill Bruno | F12: Execução do furo piloto entre os PVs 04 ao 4.1 | G12: 04 | I12: 04 | J12: Furo piloto | K12: Planejamento | L12: PDS-dezembro(1).docx | M12: =IF($A12="","",TEXT($A12,"mmmm/yyyy")) | P12: =IFERROR(_xludf.XLOOKUP($N12,Base_Enderecos!$A:$A,Base_Enderecos!$B:$B,""),"") | Q12: =IFERROR(_xludf.XLOOKUP($N12,Base_Enderecos!$A:$A,Base_Enderecos!$C:$C,""),"") | R12: =IF(OR(ISNUMBER(SEARCH("HDD",$F12)),ISNUMBER(SEARCH("MND",$F12)),ISNUMBER(SEARCH("PEAD",$F12)),ISNUMBER(SEARCH("Puxe",$J12)),ISNUMBER(SEARCH("Apoio HDD",$F12))),"MND",IF(OR(ISNUMBER(SEARCH("VCA",$F12)),ISNUMBER(SEARCH("PVC",$F12)),ISNUMBER(SEARCH("vca",$J12)),ISNUMBER(SEARCH("Transformação",$J12))),"VCA",IF(OR(ISNUMBER(SEARCH("crava",$F12)),ISNUMBER(SEARCH("tubo cravado",$F12)),ISNUMBER(SEARCH("shaft",$J12)),ISNUMBER(SEARCH("concreto",$F12))),"TUBO CRAVADO",""))) | T12: =IF($A12="","",TEXT($A12,"yyyymm")&"|"&$C12&"|"&$F12&"|"&$N12&"|"&$R12)
A13: 45992 | B13: Segunda | C13: CT Lageado | E13: Edvando | F13: VCA PV 01 | G13: 01 | I13: 01 | J13: VCA | K13: Planejamento | L13: PDS-dezembro(1).docx | M13: =IF($A13="","",TEXT($A13,"mmmm/yyyy")) | P13: =IFERROR(_xludf.XLOOKUP($N13,Base_Enderecos!$A:$A,Base_Enderecos!$B:$B,""),"") | Q13: =IFERROR(_xludf.XLOOKUP($N13,Base_Enderecos!$A:$A,Base_Enderecos!$C:$C,""),"") | R13: =IF(OR(ISNUMBER(SEARCH("HDD",$F13)),ISNUMBER(SEARCH("MND",$F13)),ISNUMBER(SEARCH("PEAD",$F13)),ISNUMBER(SEARCH("Puxe",$J13)),ISNUMBER(SEARCH("Apoio HDD",$F13))),"MND",IF(OR(ISNUMBER(SEARCH("VCA",$F13)),ISNUMBER(SEARCH("PVC",$F13)),ISNUMBER(SEARCH("vca",$J13)),ISNUMBER(SEARCH("Transformação",$J13))),"VCA",IF(OR(ISNUMBER(SEARCH("crava",$F13)),ISNUMBER(SEARCH("tubo cravado",$F13)),ISNUMBER(SEARCH("shaft",$J13)),ISNUMBER(SEARCH("concreto",$F13))),"TUBO CRAVADO",""))) | T13: =IF($A13="","",TEXT($A13,"yyyymm")&"|"&$C13&"|"&$F13&"|"&$N13&"|"&$R13)
A14: 45992 | B14: Segunda | C14: CT Lageado | E14: Paulo | F14: VCA entre os PVs 1.1 ao 1.2 | G14: 1.1 | I14: 1.1 | J14: VCA | K14: Planejamento | L14: PDS-dezembro(1).docx | M14: =IF($A14="","",TEXT($A14,"mmmm/yyyy")) | P14: =IFERROR(_xludf.XLOOKUP($N14,Base_Enderecos!$A:$A,Base_Enderecos!$B:$B,""),"") | Q14: =IFERROR(_xludf.XLOOKUP($N14,Base_Enderecos!$A:$A,Base_Enderecos!$C:$C,""),"") | R14: =IF(OR(ISNUMBER(SEARCH("HDD",$F14)),ISNUMBER(SEARCH("MND",$F14)),ISNUMBER(SEARCH("PEAD",$F14)),ISNUMBER(SEARCH("Puxe",$J14)),ISNUMBER(SEARCH("Apoio HDD",$F14))),"MND",IF(OR(ISNUMBER(SEARCH("VCA",$F14)),ISNUMBER(SEARCH("PVC",$F14)),ISNUMBER(SEARCH("vca",$J14)),ISNUMBER(SEARCH("Transformação",$J14))),"VCA",IF(OR(ISNUMBER(SEARCH("crava",$F14)),ISNUMBER(SEARCH("tubo cravado",$F14)),ISNUMBER(SEARCH("shaft",$J14)),ISNUMBER(SEARCH("concreto",$F14))),"TUBO CRAVADO",""))) | T14: =IF($A14="","",TEXT($A14,"yyyymm")&"|"&$C14&"|"&$F14&"|"&$N14&"|"&$R14)
A15: 45992 | B15: Segunda | C15: CT Lageado | E15: Valter | F15: Transformação PV 1.3 | G15: 1.3 | I15: 1.3 | J15: Transformação | K15: Planejamento | L15: PDS-dezembro(1).docx | M15: =IF($A15="","",TEXT($A15,"mmmm/yyyy")) | P15: =IFERROR(_xludf.XLOOKUP($N15,Base_Enderecos!$A:$A,Base_Enderecos!$B:$B,""),"") | Q15: =IFERROR(_xludf.XLOOKUP($N15,Base_Enderecos!$A:$A,Base_Enderecos!$C:$C,""),"") | R15: =IF(OR(ISNUMBER(SEARCH("HDD",$F15)),ISNUMBER(SEARCH("MND",$F15)),ISNUMBER(SEARCH("PEAD",$F15)),ISNUMBER(SEARCH("Puxe",$J15)),ISNUMBER(SEARCH("Apoio HDD",$F15))),"MND",IF(OR(ISNUMBER(SEARCH("VCA",$F15)),ISNUMBER(SEARCH("PVC",$F15)),ISNUMBER(SEARCH("vca",$J15)),ISNUMBER(SEARCH("Transformação",$J15))),"VCA",IF(OR(ISNUMBER(SEARCH("crava",$F15)),ISNUMBER(SEARCH("tubo cravado",$F15)),ISNUMBER(SEARCH("shaft",$J15)),ISNUMBER(SEARCH("concreto",$F15))),"TUBO CRAVADO",""))) | T15: =IF($A15="","",TEXT($A15,"yyyymm")&"|"&$C15&"|"&$F15&"|"&$N15&"|"&$R15)
A16: 45992 | B16: Segunda | C16: CT Benfica | E16: Marcio | F16: Apoio HDD entre PVs 11 a 12 | G16: 11 | I16: 11 | J16: Apoio HDD | K16: Planejamento | L16: PDS-dezembro(1).docx | M16: =IF($A16="","",TEXT($A16,"mmmm/yyyy")) | P16: =IFERROR(_xludf.XLOOKUP($N16,Base_Enderecos!$A:$A,Base_Enderecos!$B:$B,""),"") | Q16: =IFERROR(_xludf.XLOOKUP($N16,Base_Enderecos!$A:$A,Base_Enderecos!$C:$C,""),"") | R16: =IF(OR(ISNUMBER(SEARCH("HDD",$F16)),ISNUMBER(SEARCH("MND",$F16)),ISNUMBER(SEARCH("PEAD",$F16)),ISNUMBER(SEARCH("Puxe",$J16)),ISNUMBER(SEARCH("Apoio HDD",$F16))),"MND",IF(OR(ISNUMBER(SEARCH("VCA",$F16)),ISNUMBER(SEARCH("PVC",$F16)),ISNUMBER(SEARCH("vca",$J16)),ISNUMBER(SEARCH("Transformação",$J16))),"VCA",IF(OR(ISNUMBER(SEARCH("crava",$F16)),ISNUMBER(SEARCH("tubo cravado",$F16)),ISNUMBER(SEARCH("shaft",$J16)),ISNUMBER(SEARCH("concreto",$F16))),"TUBO CRAVADO",""))) | T16: =IF($A16="","",TEXT($A16,"yyyymm")&"|"&$C16&"|"&$F16&"|"&$N16&"|"&$R16)
... A18: 45992 | B18: Segunda | C18: CT Souto Maior | E18: César | F18: realizando ligações entre os PV 05 ao 7.2 | G18: 05 | I18: 05 | J18: Ligações | K18: Planejamento | L18: PDS-dezembro(1).docx | M18: =IF($A18="","",TEXT($A18,"mmmm/yyyy")) | P18: =IFERROR(_xludf.XLOOKUP($N18,Base_Enderecos!$A:$A,Base_Enderecos!$B:$B,""),"") | Q18: =IFERROR(_xludf.XLOOKUP($N18,Base_Enderecos!$A:$A,Base_Enderecos!$C:$C,""),"") | R18: =IF(OR(ISNUMBER(SEARCH("HDD",$F18)),ISNUMBER(SEARCH("MND",$F18)),ISNUMBER(SEARCH("PEAD",$F18)),ISNUMBER(SEARCH("Puxe",$J18)),ISNUMBER(SEARCH("Apoio HDD",$F18))),"MND",IF(OR(ISNUMBER(SEARCH("VCA",$F18)),ISNUMBER(SEARCH("PVC",$F18)),ISNUMBER(SEARCH("vca",$J18)),ISNUMBER(SEARCH("Transformação",$J18))),"VCA",IF(OR(ISNUMBER(SEARCH("crava",$F18)),ISNUMBER(SEARCH("tubo cravado",$F18)),ISNUMBER(SEARCH("shaft",$J18)),ISNUMBER(SEARCH("concreto",$F18))),"TUBO CRAVADO",""))) | T18: =IF($A18="","",TEXT($A18,"yyyymm")&"|"&$C18&"|"&$F18&"|"&$N18&"|"&$R18)
A19: 45992 | B19: Segunda | C19: Demais trabalhos | E19: Guindauto (Rodrigo) | F19: Apoio as equipes | K19: Planejamento | L19: PDS-dezembro(1).docx | M19: =IF($A19="","",TEXT($A19,"mmmm/yyyy")) | P19: =IFERROR(_xludf.XLOOKUP($N19,Base_Enderecos!$A:$A,Base_Enderecos!$B:$B,""),"") | Q19: =IFERROR(_xludf.XLOOKUP($N19,Base_Enderecos!$A:$A,Base_Enderecos!$C:$C,""),"") | R19: =IF(OR(ISNUMBER(SEARCH("HDD",$F19)),ISNUMBER(SEARCH("MND",$F19)),ISNUMBER(SEARCH("PEAD",$F19)),ISNUMBER(SEARCH("Puxe",$J19)),ISNUMBER(SEARCH("Apoio HDD",$F19))),"MND",IF(OR(ISNUMBER(SEARCH("VCA",$F19)),ISNUMBER(SEARCH("PVC",$F19)),ISNUMBER(SEARCH("vca",$J19)),ISNUMBER(SEARCH("Transformação",$J19))),"VCA",IF(OR(ISNUMBER(SEARCH("crava",$F19)),ISNUMBER(SEARCH("tubo cravado",$F19)),ISNUMBER(SEARCH("shaft",$J19)),ISNUMBER(SEARCH("concreto",$F19))),"TUBO CRAVADO",""))) | T19: =IF($A19="","",TEXT($A19,"yyyymm")&"|"&$C19&"|"&$F19&"|"&$N19&"|"&$R19)
A20: 45992 | B20: Segunda | C20: Demais trabalhos | E20: Guindauto (Márcio) | F20: Apoio as Equipe | K20: Planejamento | L20: PDS-dezembro(1).docx | M20: =IF($A20="","",TEXT($A20,"mmmm/yyyy")) | P20: =IFERROR(_xludf.XLOOKUP($N20,Base_Enderecos!$A:$A,Base_Enderecos!$B:$B,""),"") | Q20: =IFERROR(_xludf.XLOOKUP($N20,Base_Enderecos!$A:$A,Base_Enderecos!$C:$C,""),"") | R20: =IF(OR(ISNUMBER(SEARCH("HDD",$F20)),ISNUMBER(SEARCH("MND",$F20)),ISNUMBER(SEARCH("PEAD",$F20)),ISNUMBER(SEARCH("Puxe",$J20)),ISNUMBER(SEARCH("Apoio HDD",$F20))),"MND",IF(OR(ISNUMBER(SEARCH("VCA",$F20)),ISNUMBER(SEARCH("PVC",$F20)),ISNUMBER(SEARCH("vca",$J20)),ISNUMBER(SEARCH("Transformação",$J20))),"VCA",IF(OR(ISNUMBER(SEARCH("crava",$F20)),ISNUMBER(SEARCH("tubo cravado",$F20)),ISNUMBER(SEARCH("shaft",$J20)),ISNUMBER(SEARCH("concreto",$F20))),"TUBO CRAVADO",""))) | T20: =IF($A20="","",TEXT($A20,"yyyymm")&"|"&$C20&"|"&$F20&"|"&$N20&"|"&$R20)
A21: 45992 | B21: Segunda | C21: Vacal | E21: Apoio Marcio PV 12 Benfica | F21: Apoio Vacal | J21: Vacal | K21: Apoio | L21: PDS-dezembro(1).docx | M21: =IF($A21="","",TEXT($A21,"mmmm/yyyy")) | P21: =IFERROR(_xludf.XLOOKUP($N21,Base_Enderecos!$A:$A,Base_Enderecos!$B:$B,""),"") | Q21: =IFERROR(_xludf.XLOOKUP($N21,Base_Enderecos!$A:$A,Base_Enderecos!$C:$C,""),"") | R21: =IF(OR(ISNUMBER(SEARCH("HDD",$F21)),ISNUMBER(SEARCH("MND",$F21)),ISNUMBER(SEARCH("PEAD",$F21)),ISNUMBER(SEARCH("Puxe",$J21)),ISNUMBER(SEARCH("Apoio HDD",$F21))),"MND",IF(OR(ISNUMBER(SEARCH("VCA",$F21)),ISNUMBER(SEARCH("PVC",$F21)),ISNUMBER(SEARCH("vca",$J21)),ISNUMBER(SEARCH("Transformação",$J21))),"VCA",IF(OR(ISNUMBER(SEARCH("crava",$F21)),ISNUMBER(SEARCH("tubo cravado",$F21)),ISNUMBER(SEARCH("shaft",$J21)),ISNUMBER(SEARCH("concreto",$F21))),"TUBO CRAVADO",""))) | T21: =IF($A21="","",TEXT($A21,"yyyymm")&"|"&$C21&"|"&$F21&"|"&$N21&"|"&$R21)
A22: 45992 | B22: Segunda | C22: Vacal | E22: Apoio Marcio PV 12 Benfica | F22: Apoio Vacal | J22: Vacal | K22: Apoio | L22: PDS-dezembro(1).docx | M22: =IF($A22="","",TEXT($A22,"mmmm/yyyy")) | P22: =IFERROR(_xludf.XLOOKUP($N22,Base_Enderecos!$A:$A,Base_Enderecos!$B:$B,""),"") | Q22: =IFERROR(_xludf.XLOOKUP($N22,Base_Enderecos!$A:$A,Base_Enderecos!$C:$C,""),"") | R22: =IF(OR(ISNUMBER(SEARCH("HDD",$F22)),ISNUMBER(SEARCH("MND",$F22)),ISNUMBER(SEARCH("PEAD",$F22)),ISNUMBER(SEARCH("Puxe",$J22)),ISNUMBER(SEARCH("Apoio HDD",$F22))),"MND",IF(OR(ISNUMBER(SEARCH("VCA",$F22)),ISNUMBER(SEARCH("PVC",$F22)),ISNUMBER(SEARCH("vca",$J22)),ISNUMBER(SEARCH("Transformação",$J22))),"VCA",IF(OR(ISNUMBER(SEARCH("crava",$F22)),ISNUMBER(SEARCH("tubo cravado",$F22)),ISNUMBER(SEARCH("shaft",$J22)),ISNUMBER(SEARCH("concreto",$F22))),"TUBO CRAVADO",""))) | T22: =IF($A22="","",TEXT($A22,"yyyymm")&"|"&$C22&"|"&$F22&"|"&$N22&"|"&$R22)
A23: 45994 | B23: Quarta | C23: Mar de Coral | E23: LS | F23: Escavação mecânica e montagem de armco PV 01 | G23: 01 | I23: 01 | J23: Escavação | K23: Planejamento | L23: PDS-dezembro(1).docx | M23: =IF($A23="","",TEXT($A23,"mmmm/yyyy")) | P23: =IFERROR(_xludf.XLOOKUP($N23,Base_Enderecos!$A:$A,Base_Enderecos!$B:$B,""),"") | Q23: =IFERROR(_xludf.XLOOKUP($N23,Base_Enderecos!$A:$A,Base_Enderecos!$C:$C,""),"") | R23: =IF(OR(ISNUMBER(SEARCH("HDD",$F23)),ISNUMBER(SEARCH("MND",$F23)),ISNUMBER(SEARCH("PEAD",$F23)),ISNUMBER(SEARCH("Puxe",$J23)),ISNUMBER(SEARCH("Apoio HDD",$F23))),"MND",IF(OR(ISNUMBER(SEARCH("VCA",$F23)),ISNUMBER(SEARCH("PVC",$F23)),ISNUMBER(SEARCH("vca",$J23)),ISNUMBER(SEARCH("Transformação",$J23))),"VCA",IF(OR(ISNUMBER(SEARCH("crava",$F23)),ISNUMBER(SEARCH("tubo cravado",$F23)),ISNUMBER(SEARCH("shaft",$J23)),ISNUMBER(SEARCH("concreto",$F23))),"TUBO CRAVADO",""))) | T23: =IF($A23="","",TEXT($A23,"yyyymm")&"|"&$C23&"|"&$F23&"|"&$N23&"|"&$R23)
A24: 45994 | B24: Quarta | C24: CT Lageado | E24: Higor | F24: transformar PV 1.3 | G24: 1.3 | I24: 1.3 | K24: Planejamento | L24: PDS-dezembro(1).docx | M24: =IF($A24="","",TEXT($A24,"mmmm/yyyy")) | P24: =IFERROR(_xludf.XLOOKUP($N24,Base_Enderecos!$A:$A,Base_Enderecos!$B:$B,""),"") | Q24: =IFERROR(_xludf.XLOOKUP($N24,Base_Enderecos!$A:$A,Base_Enderecos!$C:$C,""),"") | R24: =IF(OR(ISNUMBER(SEARCH("HDD",$F24)),ISNUMBER(SEARCH("MND",$F24)),ISNUMBER(SEARCH("PEAD",$F24)),ISNUMBER(SEARCH("Puxe",$J24)),ISNUMBER(SEARCH("Apoio HDD",$F24))),"MND",IF(OR(ISNUMBER(SEARCH("VCA",$F24)),ISNUMBER(SEARCH("PVC",$F24)),ISNUMBER(SEARCH("vca",$J24)),ISNUMBER(SEARCH("Transformação",$J24))),"VCA",IF(OR(ISNUMBER(SEARCH("crava",$F24)),ISNUMBER(SEARCH("tubo cravado",$F24)),ISNUMBER(SEARCH("shaft",$J24)),ISNUMBER(SEARCH("concreto",$F24))),"TUBO CRAVADO",""))) | T24: =IF($A24="","",TEXT($A24,"yyyymm")&"|"&$C24&"|"&$F24&"|"&$N24&"|"&$R24)
A25: 45994 | B25: Quarta | C25: CT Lageado | E25: Natalino | F25: Apoio HDD entre PVs 03 a 05 | G25: 03 | I25: 03 | J25: Apoio HDD | K25: Planejamento | L25: PDS-dezembro(1).docx | M25: =IF($A25="","",TEXT($A25,"mmmm/yyyy")) | P25: =IFERROR(_xludf.XLOOKUP($N25,Base_Enderecos!$A:$A,Base_Enderecos!$B:$B,""),"") | Q25: =IFERROR(_xludf.XLOOKUP($N25,Base_Enderecos!$A:$A,Base_Enderecos!$C:$C,""),"") | R25: =IF(OR(ISNUMBER(SEARCH("HDD",$F25)),ISNUMBER(SEARCH("MND",$F25)),ISNUMBER(SEARCH("PEAD",$F25)),ISNUMBER(SEARCH("Puxe",$J25)),ISNUMBER(SEARCH("Apoio HDD",$F25))),"MND",IF(OR(ISNUMBER(SEARCH("VCA",$F25)),ISNUMBER(SEARCH("PVC",$F25)),ISNUMBER(SEARCH("vca",$J25)),ISNUMBER(SEARCH("Transformação",$J25))),"VCA",IF(OR(ISNUMBER(SEARCH("crava",$F25)),ISNUMBER(SEARCH("tubo cravado",$F25)),ISNUMBER(SEARCH("shaft",$J25)),ISNUMBER(SEARCH("concreto",$F25))),"TUBO CRAVADO",""))) | T25: =IF($A25="","",TEXT($A25,"yyyymm")&"|"&$C25&"|"&$F25&"|"&$N25&"|"&$R25)
A26: 45994 | B26: Quarta | C26: CT Lageado | E26: WJ (Edson) | F26: Execução do furo piloto entre os PVs 03 ao 05 | G26: 03 | I26: 03 | J26: Furo piloto | K26: Planejamento | L26: PDS-dezembro(1).docx | M26: =IF($A26="","",TEXT($A26,"mmmm/yyyy")) | P26: =IFERROR(_xludf.XLOOKUP($N26,Base_Enderecos!$A:$A,Base_Enderecos!$B:$B,""),"") | Q26: =IFERROR(_xludf.XLOOKUP($N26,Base_Enderecos!$A:$A,Base_Enderecos!$C:$C,""),"") | R26: =IF(OR(ISNUMBER(SEARCH("HDD",$F26)),ISNUMBER(SEARCH("MND",$F26)),ISNUMBER(SEARCH("PEAD",$F26)),ISNUMBER(SEARCH("Puxe",$J26)),ISNUMBER(SEARCH("Apoio HDD",$F26))),"MND",IF(OR(ISNUMBER(SEARCH("VCA",$F26)),ISNUMBER(SEARCH("PVC",$F26)),ISNUMBER(SEARCH("vca",$J26)),ISNUMBER(SEARCH("Transformação",$J26))),"VCA",IF(OR(ISNUMBER(SEARCH("crava",$F26)),ISNUMBER(SEARCH("tubo cravado",$F26)),ISNUMBER(SEARCH("shaft",$J26)),ISNUMBER(SEARCH("concreto",$F26))),"TUBO CRAVADO",""))) | T26: =IF($A26="","",TEXT($A26,"yyyymm")&"|"&$C26&"|"&$F26&"|"&$N26&"|"&$R26)
A27: 45994 | B27: Quarta | C27: CT Lageado | E27: Fabrício | F27: Apoio HDD entre PVs 5.1 a 05 | G27: 5.1 | I27: 5.1 | J27: Apoio HDD | K27: Planejamento | L27: PDS-dezembro(1).docx | M27: =IF($A27="","",TEXT($A27,"mmmm/yyyy")) | P27: =IFERROR(_xludf.XLOOKUP($N27,Base_Enderecos!$A:$A,Base_Enderecos!$B:$B,""),"") | Q27: =IFERROR(_xludf.XLOOKUP($N27,Base_Enderecos!$A:$A,Base_Enderecos!$C:$C,""),"") | R27: =IF(OR(ISNUMBER(SEARCH("HDD",$F27)),ISNUMBER(SEARCH("MND",$F27)),ISNUMBER(SEARCH("PEAD",$F27)),ISNUMBER(SEARCH("Puxe",$J27)),ISNUMBER(SEARCH("Apoio HDD",$F27))),"MND",IF(OR(ISNUMBER(SEARCH("VCA",$F27)),ISNUMBER(SEARCH("PVC",$F27)),ISNUMBER(SEARCH("vca",$J27)),ISNUMBER(SEARCH("Transformação",$J27))),"VCA",IF(OR(ISNUMBER(SEARCH("crava",$F27)),ISNUMBER(SEARCH("tubo cravado",$F27)),ISNUMBER(SEARCH("shaft",$J27)),ISNUMBER(SEARCH("concreto",$F27))),"TUBO CRAVADO",""))) | T27: =IF($A27="","",TEXT($A27,"yyyymm")&"|"&$C27&"|"&$F27&"|"&$N27&"|"&$R27)
A28: 45994 | B28: Quarta | C28: CT Lageado | E28: Work Drill Bruno | F28: Execução do furo piloto entre os PVs 5.1 ao 05 | G28: 5.1 | I28: 5.1 | J28: Furo piloto | K28: Planejamento | L28: PDS-dezembro(1).docx | M28: =IF($A28="","",TEXT($A28,"mmmm/yyyy")) | P28: =IFERROR(_xludf.XLOOKUP($N28,Base_Enderecos!$A:$A,Base_Enderecos!$B:$B,""),"") | Q28: =IFERROR(_xludf.XLOOKUP($N28,Base_Enderecos!$A:$A,Base_Enderecos!$C:$C,""),"") | R28: =IF(OR(ISNUMBER(SEARCH("HDD",$F28)),ISNUMBER(SEARCH("MND",$F28)),ISNUMBER(SEARCH("PEAD",$F28)),ISNUMBER(SEARCH("Puxe",$J28)),ISNUMBER(SEARCH("Apoio HDD",$F28))),"MND",IF(OR(ISNUMBER(SEARCH("VCA",$F28)),ISNUMBER(SEARCH("PVC",$F28)),ISNUMBER(SEARCH("vca",$J28)),ISNUMBER(SEARCH("Transformação",$J28))),"VCA",IF(OR(ISNUMBER(SEARCH("crava",$F28)),ISNUMBER(SEARCH("tubo cravado",$F28)),ISNUMBER(SEARCH("shaft",$J28)),ISNUMBER(SEARCH("concreto",$F28))),"TUBO CRAVADO",""))) | T28: =IF($A28="","",TEXT($A28,"yyyymm")&"|"&$C28&"|"&$F28&"|"&$N28&"|"&$R28)
A29: 45994 | B29: Quarta | C29: CT Lageado | E29: Marcio | F29: Apoio HDD entre PVs 04 a 4.1 | G29: 04 | I29: 04 | J29: Apoio HDD | K29: Planejamento | L29: PDS-dezembro(1).docx | M29: =IF($A29="","",TEXT($A29,"mmmm/yyyy")) | P29: =IFERROR(_xludf.XLOOKUP($N29,Base_Enderecos!$A:$A,Base_Enderecos!$B:$B,""),"") | Q29: =IFERROR(_xludf.XLOOKUP($N29,Base_Enderecos!$A:$A,Base_Enderecos!$C:$C,""),"") | R29: =IF(OR(ISNUMBER(SEARCH("HDD",$F29)),ISNUMBER(SEARCH("MND",$F29)),ISNUMBER(SEARCH("PEAD",$F29)),ISNUMBER(SEARCH("Puxe",$J29)),ISNUMBER(SEARCH("Apoio HDD",$F29))),"MND",IF(OR(ISNUMBER(SEARCH("VCA",$F29)),ISNUMBER(SEARCH("PVC",$F29)),ISNUMBER(SEARCH("vca",$J29)),ISNUMBER(SEARCH("Transformação",$J29))),"VCA",IF(OR(ISNUMBER(SEARCH("crava",$F29)),ISNUMBER(SEARCH("tubo cravado",$F29)),ISNUMBER(SEARCH("shaft",$J29)),ISNUMBER(SEARCH("concreto",$F29))),"TUBO CRAVADO",""))) | T29: =IF($A29="","",TEXT($A29,"yyyymm")&"|"&$C29&"|"&$F29&"|"&$N29&"|"&$R29)
A30: 45994 | B30: Quarta | C30: CT Lageado | E30: WJ (Alex) | F30: Execução do furo piloto entre os PVs 04 ao 4.1 | G30: 04 | I30: 04 | J30: Furo piloto | K30: Planejamento | L30: PDS-dezembro(1).docx | M30: =IF($A30="","",TEXT($A30,"mmmm/yyyy")) | P30: =IFERROR(_xludf.XLOOKUP($N30,Base_Enderecos!$A:$A,Base_Enderecos!$B:$B,""),"") | Q30: =IFERROR(_xludf.XLOOKUP($N30,Base_Enderecos!$A:$A,Base_Enderecos!$C:$C,""),"") | R30: =IF(OR(ISNUMBER(SEARCH("HDD",$F30)),ISNUMBER(SEARCH("MND",$F30)),ISNUMBER(SEARCH("PEAD",$F30)),ISNUMBER(SEARCH("Puxe",$J30)),ISNUMBER(SEARCH("Apoio HDD",$F30))),"MND",IF(OR(ISNUMBER(SEARCH("VCA",$F30)),ISNUMBER(SEARCH("PVC",$F30)),ISNUMBER(SEARCH("vca",$J30)),ISNUMBER(SEARCH("Transformação",$J30))),"VCA",IF(OR(ISNUMBER(SEARCH("crava",$F30)),ISNUMBER(SEARCH("tubo cravado",$F30)),ISNUMBER(SEARCH("shaft",$J30)),ISNUMBER(SEARCH("concreto",$F30))),"TUBO CRAVADO",""))) | T30: =IF($A30="","",TEXT($A30,"yyyymm")&"|"&$C30&"|"&$F30&"|"&$N30&"|"&$R30)
A31: 45994 | B31: Quarta | C31: CT Benfica | E31: Valter | F31: Transformação PV 11 | G31: 11 | I31: 11 | J31: Transformação | K31: Planejamento | L31: PDS-dezembro(1).docx | M31: =IF($A31="","",TEXT($A31,"mmmm/yyyy")) | P31: =IFERROR(_xludf.XLOOKUP($N31,Base_Enderecos!$A:$A,Base_Enderecos!$B:$B,""),"") | Q31: =IFERROR(_xludf.XLOOKUP($N31,Base_Enderecos!$A:$A,Base_Enderecos!$C:$C,""),"") | R31: =IF(OR(ISNUMBER(SEARCH("HDD",$F31)),ISNUMBER(SEARCH("MND",$F31)),ISNUMBER(SEARCH("PEAD",$F31)),ISNUMBER(SEARCH("Puxe",$J31)),ISNUMBER(SEARCH("Apoio HDD",$F31))),"MND",IF(OR(ISNUMBER(SEARCH("VCA",$F31)),ISNUMBER(SEARCH("PVC",$F31)),ISNUMBER(SEARCH("vca",$J31)),ISNUMBER(SEARCH("Transformação",$J31))),"VCA",IF(OR(ISNUMBER(SEARCH("crava",$F31)),ISNUMBER(SEARCH("tubo cravado",$F31)),ISNUMBER(SEARCH("shaft",$J31)),ISNUMBER(SEARCH("concreto",$F31))),"TUBO CRAVADO",""))) | T31: =IF($A31="","",TEXT($A31,"yyyymm")&"|"&$C31&"|"&$F31&"|"&$N31&"|"&$R31)
A32: 45994 | B32: Quarta | C32: CT Benfica | E32: Marcelo | F32: Transformação e interligação PV 12 | G32: 12 | I32: 12 | J32: Transformação | K32: Planejamento | L32: PDS-dezembro(1).docx | M32: =IF($A32="","",TEXT($A32,"mmmm/yyyy")) | P32: =IFERROR(_xludf.XLOOKUP($N32,Base_Enderecos!$A:$A,Base_Enderecos!$B:$B,""),"") | Q32: =IFERROR(_xludf.XLOOKUP($N32,Base_Enderecos!$A:$A,Base_Enderecos!$C:$C,""),"") | R32: =IF(OR(ISNUMBER(SEARCH("HDD",$F32)),ISNUMBER(SEARCH("MND",$F32)),ISNUMBER(SEARCH("PEAD",$F32)),ISNUMBER(SEARCH("Puxe",$J32)),ISNUMBER(SEARCH("Apoio HDD",$F32))),"MND",IF(OR(ISNUMBER(SEARCH("VCA",$F32)),ISNUMBER(SEARCH("PVC",$F32)),ISNUMBER(SEARCH("vca",$J32)),ISNUMBER(SEARCH("Transformação",$J32))),"VCA",IF(OR(ISNUMBER(SEARCH("crava",$F32)),ISNUMBER(SEARCH("tubo cravado",$F32)),ISNUMBER(SEARCH("shaft",$J32)),ISNUMBER(SEARCH("concreto",$F32))),"TUBO CRAVADO",""))) | T32: =IF($A32="","",TEXT($A32,"yyyymm")&"|"&$C32&"|"&$F32&"|"&$N32&"|"&$R32)
A33: 45994 | B33: Quarta | C33: Demais trabalhos | E33: Guindauto (Rodrigo) | F33: Apoio as equipes | K33: Planejamento | L33: PDS-dezembro(1).docx | M33: =IF($A33="","",TEXT($A33,"mmmm/yyyy")) | P33: =IFERROR(_xludf.XLOOKUP($N33,Base_Enderecos!$A:$A,Base_Enderecos!$B:$B,""),"") | Q33: =IFERROR(_xludf.XLOOKUP($N33,Base_Enderecos!$A:$A,Base_Enderecos!$C:$C,""),"") | R33: =IF(OR(ISNUMBER(SEARCH("HDD",$F33)),ISNUMBER(SEARCH("MND",$F33)),ISNUMBER(SEARCH("PEAD",$F33)),ISNUMBER(SEARCH("Puxe",$J33)),ISNUMBER(SEARCH("Apoio HDD",$F33))),"MND",IF(OR(ISNUMBER(SEARCH("VCA",$F33)),ISNUMBER(SEARCH("PVC",$F33)),ISNUMBER(SEARCH("vca",$J33)),ISNUMBER(SEARCH("Transformação",$J33))),"VCA",IF(OR(ISNUMBER(SEARCH("crava",$F33)),ISNUMBER(SEARCH("tubo cravado",$F33)),ISNUMBER(SEARCH("shaft",$J33)),ISNUMBER(SEARCH("concreto",$F33))),"TUBO CRAVADO",""))) | T33: =IF($A33="","",TEXT($A33,"yyyymm")&"|"&$C33&"|"&$F33&"|"&$N33&"|"&$R33)
A34: 45994 | B34: Quarta | C34: Demais trabalhos | E34: Guindauto (Márcio) | F34: Apoio as Equipe | K34: Planejamento | L34: PDS-dezembro(1).docx | M34: =IF($A34="","",TEXT($A34,"mmmm/yyyy")) | P34: =IFERROR(_xludf.XLOOKUP($N34,Base_Enderecos!$A:$A,Base_Enderecos!$B:$B,""),"") | Q34: =IFERROR(_xludf.XLOOKUP($N34,Base_Enderecos!$A:$A,Base_Enderecos!$C:$C,""),"") | R34: =IF(OR(ISNUMBER(SEARCH("HDD",$F34)),ISNUMBER(SEARCH("MND",$F34)),ISNUMBER(SEARCH("PEAD",$F34)),ISNUMBER(SEARCH("Puxe",$J34)),ISNUMBER(SEARCH("Apoio HDD",$F34))),"MND",IF(OR(ISNUMBER(SEARCH("VCA",$F34)),ISNUMBER(SEARCH("PVC",$F34)),ISNUMBER(SEARCH("vca",$J34)),ISNUMBER(SEARCH("Transformação",$J34))),"VCA",IF(OR(ISNUMBER(SEARCH("crava",$F34)),ISNUMBER(SEARCH("tubo cravado",$F34)),ISNUMBER(SEARCH("shaft",$J34)),ISNUMBER(SEARCH("concreto",$F34))),"TUBO CRAVADO",""))) | T34: =IF($A34="","",TEXT($A34,"yyyymm")&"|"&$C34&"|"&$F34&"|"&$N34&"|"&$R34)
A35: 45994 | B35: Quarta | C35: Vacal | E35: Apoio Marcio PV 04 Lageado | F35: Apoio Vacal | J35: Vacal | K35: Apoio | L35: PDS-dezembro(1).docx | M35: =IF($A35="","",TEXT($A35,"mmmm/yyyy")) | P35: =IFERROR(_xludf.XLOOKUP($N35,Base_Enderecos!$A:$A,Base_Enderecos!$B:$B,""),"") | Q35: =IFERROR(_xludf.XLOOKUP($N35,Base_Enderecos!$A:$A,Base_Enderecos!$C:$C,""),"") | R35: =IF(OR(ISNUMBER(SEARCH("HDD",$F35)),ISNUMBER(SEARCH("MND",$F35)),ISNUMBER(SEARCH("PEAD",$F35)),ISNUMBER(SEARCH("Puxe",$J35)),ISNUMBER(SEARCH("Apoio HDD",$F35))),"MND",IF(OR(ISNUMBER(SEARCH("VCA",$F35)),ISNUMBER(SEARCH("PVC",$F35)),ISNUMBER(SEARCH("vca",$J35)),ISNUMBER(SEARCH("Transformação",$J35))),"VCA",IF(OR(ISNUMBER(SEARCH("crava",$F35)),ISNUMBER(SEARCH("tubo cravado",$F35)),ISNUMBER(SEARCH("shaft",$J35)),ISNUMBER(SEARCH("concreto",$F35))),"TUBO CRAVADO",""))) | T35: =IF($A35="","",TEXT($A35,"yyyymm")&"|"&$C35&"|"&$F35&"|"&$N35&"|"&$R35)
A36: 45994 | B36: Quarta | C36: Vacal | E36: Apoio Fabrício PV 05 Lageado | F36: Apoio Vacal | J36: Vacal | K36: Apoio | L36: PDS-dezembro(1).docx | M36: =IF($A36="","",TEXT($A36,"mmmm/yyyy")) | P36: =IFERROR(_xludf.XLOOKUP($N36,Base_Enderecos!$A:$A,Base_Enderecos!$B:$B,""),"") | Q36: =IFERROR(_xludf.XLOOKUP($N36,Base_Enderecos!$A:$A,Base_Enderecos!$C:$C,""),"") | R36: =IF(OR(ISNUMBER(SEARCH("HDD",$F36)),ISNUMBER(SEARCH("MND",$F36)),ISNUMBER(SEARCH("PEAD",$F36)),ISNUMBER(SEARCH("Puxe",$J36)),ISNUMBER(SEARCH("Apoio HDD",$F36))),"MND",IF(OR(ISNUMBER(SEARCH("VCA",$F36)),ISNUMBER(SEARCH("PVC",$F36)),ISNUMBER(SEARCH("vca",$J36)),ISNUMBER(SEARCH("Transformação",$J36))),"VCA",IF(OR(ISNUMBER(SEARCH("crava",$F36)),ISNUMBER(SEARCH("tubo cravado",$F36)),ISNUMBER(SEARCH("shaft",$J36)),ISNUMBER(SEARCH("concreto",$F36))),"TUBO CRAVADO",""))) | T36: =IF($A36="","",TEXT($A36,"yyyymm")&"|"&$C36&"|"&$F36&"|"&$N36&"|"&$R36)
A37: 45995 | B37: Quinta | C37: Miriam | E37: Paulo | F37: Transformação do PV 57 e interligação do PV 59 | G37: 57 | H37: 59 | I37: 57, 59 | J37: Transformação | K37: Planejamento | L37: PDS-dezembro(1).docx | M37: =IF($A37="","",TEXT($A37,"mmmm/yyyy")) | P37: =IFERROR(_xludf.XLOOKUP($N37,Base_Enderecos!$A:$A,Base_Enderecos!$B:$B,""),"") | Q37: =IFERROR(_xludf.XLOOKUP($N37,Base_Enderecos!$A:$A,Base_Enderecos!$C:$C,""),"") | R37: =IF(OR(ISNUMBER(SEARCH("HDD",$F37)),ISNUMBER(SEARCH("MND",$F37)),ISNUMBER(SEARCH("PEAD",$F37)),ISNUMBER(SEARCH("Puxe",$J37)),ISNUMBER(SEARCH("Apoio HDD",$F37))),"MND",IF(OR(ISNUMBER(SEARCH("VCA",$F37)),ISNUMBER(SEARCH("PVC",$F37)),ISNUMBER(SEARCH("vca",$J37)),ISNUMBER(SEARCH("Transformação",$J37))),"VCA",IF(OR(ISNUMBER(SEARCH("crava",$F37)),ISNUMBER(SEARCH("tubo cravado",$F37)),ISNUMBER(SEARCH("shaft",$J37)),ISNUMBER(SEARCH("concreto",$F37))),"TUBO CRAVADO",""))) | T37: =IF($A37="","",TEXT($A37,"yyyymm")&"|"&$C37&"|"&$F37&"|"&$N37&"|"&$R37)
A38: 45995 | B38: Quinta | C38: Mar de Coral | E38: LS | F38: Escavação mecânica e montagem de armco PV 01 | G38: 01 | I38: 01 | J38: Escavação | K38: Planejamento | L38: PDS-dezembro(1).docx | M38: =IF($A38="","",TEXT($A38,"mmmm/yyyy")) | P38: =IFERROR(_xludf.XLOOKUP($N38,Base_Enderecos!$A:$A,Base_Enderecos!$B:$B,""),"") | Q38: =IFERROR(_xludf.XLOOKUP($N38,Base_Enderecos!$A:$A,Base_Enderecos!$C:$C,""),"") | R38: =IF(OR(ISNUMBER(SEARCH("HDD",$F38)),ISNUMBER(SEARCH("MND",$F38)),ISNUMBER(SEARCH("PEAD",$F38)),ISNUMBER(SEARCH("Puxe",$J38)),ISNUMBER(SEARCH("Apoio HDD",$F38))),"MND",IF(OR(ISNUMBER(SEARCH("VCA",$F38)),ISNUMBER(SEARCH("PVC",$F38)),ISNUMBER(SEARCH("vca",$J38)),ISNUMBER(SEARCH("Transformação",$J38))),"VCA",IF(OR(ISNUMBER(SEARCH("crava",$F38)),ISNUMBER(SEARCH("tubo cravado",$F38)),ISNUMBER(SEARCH("shaft",$J38)),ISNUMBER(SEARCH("concreto",$F38))),"TUBO CRAVADO",""))) | T38: =IF($A38="","",TEXT($A38,"yyyymm")&"|"&$C38&"|"&$F38&"|"&$N38&"|"&$R38)
A39: 45995 | B39: Quinta | C39: CT Lageado | E39: Cesar | F39: transformar PV 5.1 | G39: 5.1 | I39: 5.1 | K39: Planejamento | L39: PDS-dezembro(1).docx | M39: =IF($A39="","",TEXT($A39,"mmmm/yyyy")) | P39: =IFERROR(_xludf.XLOOKUP($N39,Base_Enderecos!$A:$A,Base_Enderecos!$B:$B,""),"") | Q39: =IFERROR(_xludf.XLOOKUP($N39,Base_Enderecos!$A:$A,Base_Enderecos!$C:$C,""),"") | R39: =IF(OR(ISNUMBER(SEARCH("HDD",$F39)),ISNUMBER(SEARCH("MND",$F39)),ISNUMBER(SEARCH("PEAD",$F39)),ISNUMBER(SEARCH("Puxe",$J39)),ISNUMBER(SEARCH("Apoio HDD",$F39))),"MND",IF(OR(ISNUMBER(SEARCH("VCA",$F39)),ISNUMBER(SEARCH("PVC",$F39)),ISNUMBER(SEARCH("vca",$J39)),ISNUMBER(SEARCH("Transformação",$J39))),"VCA",IF(OR(ISNUMBER(SEARCH("crava",$F39)),ISNUMBER(SEARCH("tubo cravado",$F39)),ISNUMBER(SEARCH("shaft",$J39)),ISNUMBER(SEARCH("concreto",$F39))),"TUBO CRAVADO",""))) | T39: =IF($A39="","",TEXT($A39,"yyyymm")&"|"&$C39&"|"&$F39&"|"&$N39&"|"&$R39)
A40: 45995 | B40: Quinta | C40: CT Lageado | E40: Higor | F40: Transformar PV 1.5 | G40: 1.5 | I40: 1.5 | K40: Planejamento | L40: PDS-dezembro(1).docx | M40: =IF($A40="","",TEXT($A40,"mmmm/yyyy")) | P40: =IFERROR(_xludf.XLOOKUP($N40,Base_Enderecos!$A:$A,Base_Enderecos!$B:$B,""),"") | Q40: =IFERROR(_xludf.XLOOKUP($N40,Base_Enderecos!$A:$A,Base_Enderecos!$C:$C,""),"") | R40: =IF(OR(ISNUMBER(SEARCH("HDD",$F40)),ISNUMBER(SEARCH("MND",$F40)),ISNUMBER(SEARCH("PEAD",$F40)),ISNUMBER(SEARCH("Puxe",$J40)),ISNUMBER(SEARCH("Apoio HDD",$F40))),"MND",IF(OR(ISNUMBER(SEARCH("VCA",$F40)),ISNUMBER(SEARCH("PVC",$F40)),ISNUMBER(SEARCH("vca",$J40)),ISNUMBER(SEARCH("Transformação",$J40))),"VCA",IF(OR(ISNUMBER(SEARCH("crava",$F40)),ISNUMBER(SEARCH("tubo cravado",$F40)),ISNUMBER(SEARCH("shaft",$J40)),ISNUMBER(SEARCH("concreto",$F40))),"TUBO CRAVADO",""))) | T40: =IF($A40="","",TEXT($A40,"yyyymm")&"|"&$C40&"|"&$F40&"|"&$N40&"|"&$R40)
A41: 45995 | B41: Quinta | C41: CT Lageado | E41: Natalino | F41: Apoio HDD entre PVs 08 a 8.1 | G41: 08 | I41: 08 | J41: Apoio HDD | K41: Planejamento | L41: PDS-dezembro(1).docx | M41: =IF($A41="","",TEXT($A41,"mmmm/yyyy")) | P41: =IFERROR(_xludf.XLOOKUP($N41,Base_Enderecos!$A:$A,Base_Enderecos!$B:$B,""),"") | Q41: =IFERROR(_xludf.XLOOKUP($N41,Base_Enderecos!$A:$A,Base_Enderecos!$C:$C,""),"") | R41: =IF(OR(ISNUMBER(SEARCH("HDD",$F41)),ISNUMBER(SEARCH("MND",$F41)),ISNUMBER(SEARCH("PEAD",$F41)),ISNUMBER(SEARCH("Puxe",$J41)),ISNUMBER(SEARCH("Apoio HDD",$F41))),"MND",IF(OR(ISNUMBER(SEARCH("VCA",$F41)),ISNUMBER(SEARCH("PVC",$F41)),ISNUMBER(SEARCH("vca",$J41)),ISNUMBER(SEARCH("Transformação",$J41))),"VCA",IF(OR(ISNUMBER(SEARCH("crava",$F41)),ISNUMBER(SEARCH("tubo cravado",$F41)),ISNUMBER(SEARCH("shaft",$J41)),ISNUMBER(SEARCH("concreto",$F41))),"TUBO CRAVADO",""))) | T41: =IF($A41="","",TEXT($A41,"yyyymm")&"|"&$C41&"|"&$F41&"|"&$N41&"|"&$R41)
A42: 45995 | B42: Quinta | C42: CT Lageado | E42: Edivando | F42: Transformação PV 1.1 | G42: 1.1 | I42: 1.1 | J42: Transformação | K42: Planejamento | L42: PDS-dezembro(1).docx | M42: =IF($A42="","",TEXT($A42,"mmmm/yyyy")) | P42: =IFERROR(_xludf.XLOOKUP($N42,Base_Enderecos!$A:$A,Base_Enderecos!$B:$B,""),"") | Q42: =IFERROR(_xludf.XLOOKUP($N42,Base_Enderecos!$A:$A,Base_Enderecos!$C:$C,""),"") | R42: =IF(OR(ISNUMBER(SEARCH("HDD",$F42)),ISNUMBER(SEARCH("MND",$F42)),ISNUMBER(SEARCH("PEAD",$F42)),ISNUMBER(SEARCH("Puxe",$J42)),ISNUMBER(SEARCH("Apoio HDD",$F42))),"MND",IF(OR(ISNUMBER(SEARCH("VCA",$F42)),ISNUMBER(SEARCH("PVC",$F42)),ISNUMBER(SEARCH("vca",$J42)),ISNUMBER(SEARCH("Transformação",$J42))),"VCA",IF(OR(ISNUMBER(SEARCH("crava",$F42)),ISNUMBER(SEARCH("tubo cravado",$F42)),ISNUMBER(SEARCH("shaft",$J42)),ISNUMBER(SEARCH("concreto",$F42))),"TUBO CRAVADO",""))) | T42: =IF($A42="","",TEXT($A42,"yyyymm")&"|"&$C42&"|"&$F42&"|"&$N42&"|"&$R42)
...

Sheet Resumo
A1: Resumo da extração
A3: Indicador | B3: Valor | D3: Mês | E3: Linhas extraídas | G3: Top obras | H3: Qtd. linhas
A4: Total de linhas | B4: 2161 | D4: 2025-12 | E4: 248 | G4: Vacal | H4: 383
A5: Total de obras | B5: 55 | D5: 2026-01 | E5: 366 | G5: CT CONCEIÇÃO | H5: 195
A6: Total de tipos de atividade | B6: 24 | D6: 2026-02 | E6: 449 | G6: CT MAR DE CORAL | H6: 173
A7: Arquivos consolidados | B7: 5 | D7: 2026-03 | E7: 505 | G7: Guindauto | H7: 161
D8: 2026-04 | E8: 564 | G8: CT Mar de Coral | H8: 114
D9: 2026-05 | E9: 29 | G9: CTS LUIS BOTELHO MOURÃO | H9: 114
G10: CT ÁGUA VERMELHA M.D. e M.E | H10: 101
G11: CT Lageado | H11: 89
G12: CT ÁGUA VERMELHA M.D | H12: 72
G13: CT Lourdes | H13: 70
G14: CT AGUA VERMELHA M.D | H14: 56
G15: CT ÁGUA VERMELHA M.D. | H15: 44
G16: CT AGUA VERMELHA M.E | H16: 36
G17: CT LOURDES | H17: 35
G18: RCE FCO. SOUTO MAIOR | H18: 34

Sheet Base_Enderecos
A1: RUA | B1: MUNICIPIO | C1: SUBPREFEITURA | D1: OBS
A2: Preencher rua igual ao PDS | B2: São Paulo | C2: Preencher subprefeitura | D2: Exemplo: cadastrar uma vez e puxa automático

Sheet Parametros_Relatorio
A1: Campo | B1: Preenchimento
A2: CONTRATO
A3: CONTRATADA | B3: Consórcio XXXXX Pacote XX
A4: OBJETO
A5: MES_REFERENCIA
A6: ELABORADO_POR
A7: APROVADO_POR
A8: REVISAO | B8: 00
A9: DATA_REVISAO
A10: COMENTARIOS_REVISAO | B10: Revisão inicial
A11: OBS | B11: Campos usados futuramente para gerar o Word do relatório.
A12: STATUS | B12: Base pronta

Sheet Orientacoes_Relatorio
A1: Orientação | B1: Detalhe
A2: Não alterei a estrutura original | B2: As colunas A:L foram preservadas. As novas colunas entram a partir da M.
A3: MES_REF | B3: Calculado automaticamente pela Data da coluna A.
A4: RUA | B4: Preencher manualmente no PDS.
A5: NUMERO | B5: Preencher manualmente no PDS.
A6: MUNICIPIO | B6: Puxa da aba Base_Enderecos pela Rua. Pode preencher manualmente se preferir.
A7: SUBPREFEITURA | B7: Puxa da aba Base_Enderecos pela Rua. Pode preencher manualmente se preferir.
A8: METODO_PADRAO | B8: Tenta classificar como MND, VCA ou TUBO CRAVADO com base na atividade/tipo.
A9: EXTENSAO_M | B9: Preencher quando houver produção em metro.
A10: CHAVE_RELATORIO | B10: Agrupa mês, obra, atividade, rua e método para não repetir no relatório.
A11: OBS_RELATORIO | B11: Campo livre para comentário mensal.
A12: Próximo passo | B12: Depois de preencher Rua/Número, podemos gerar o Word automático.
